Workbook

Sheet Start Here
B2: Capacity, Scheduling & Engagement -- the unabridged variable workbook
B3: Every variable in the 8.13 inventory, placed under the three arenas of the vendor one-pager, in the same plain language. Built to be edited as we talk through each scenario, and to be the source the future-state maps are drawn from.
B6: What is in here
B7: Master List | C7: One row per variable — 93 of them, the full inventory with nothing dropped. This is the sheet we edit together. Six rows are highlighted: the incentives row, which the vendor questionnaire has asked about since 21 Aug but which carried no ID, and five variables the 13 Aug session confirmed as real but never had a row drafted. All six need MVP, gating and posture confirmed.
B8: Roles | C8: Who each role is, and the colour it carries on the current-state flow maps. Use these names in the two owner columns so the future-state maps stay consistent.
B9: Lists | C9: The permitted values behind the drop-downs. Change a value here and the drop-down changes everywhere.
B11: How to read a row
B12: Arena (8.19 workbook) | C12: Straight from the Module column of the 19 Aug workbook. That column is authoritative — change it there, not here.
B13: Also touches | C13: The other arenas the variable shows up in. Plenty are shared — that is expected, not a problem to resolve.
B14: One-pager group | C14: The ten group headings from the vendor one-pager. Part B of the questionnaire scores exactly these groups.
B15: Placement check | C15: Whether the workbook and the one-pager agree on where this belongs. They disagree on a number of rows — neither is wrong, the workbook is the internal model and the one-pager is the vendor view, but a vendor answering under one heading while we score under another gives a false coverage read. The disagreements are surfaced here rather than resolved.
B16: In plain terms | C16: Written for a reader with no home-health background. If a sentence needs clinical knowledge to parse, it needs rewriting.
B17: Who does the work today | C17: The role that physically performs the task. Shared ownership is fine — 'DCS and Scheduler' is a real answer.
B18: Who reads it and decides today | C18: The role that looks at the result and acts. Often a different person from the one who does the work, and sometimes the honest answer is nobody — those rows are marked '— no one today' and they are the interesting ones.
B19: Where the information lives today | C19: The system, screen or note it sits in. Shaded by how sure we are — see the confidence key below.
B20: Future state -- the tool's role | C20: Automate (the tool does it), Assist (the tool proposes, a person confirms), Surface (the tool shows, a person decides), Stays manual (unchanged).
B21: Future state -- who decides | C21: For Assist and Surface rows, the person who confirms or acts. For Automate rows, who owns the exception when automation cannot resolve it.
B22: Trigger / how often | C22: What sets the task off and at what rhythm. This is the column the future-state maps are built from — a map is a sequence of triggers.
B23: Confidence key -- where to jump in first | C23: Stable = record it once and it holds. Drifts = it goes stale unless somebody keeps asking, so it needs a standing engagement mechanism, not a field captured at start of care. Live/computed = recalculated, no decay problem. This is the contact = the row is the outbound work itself.
... B26: Low | C26: Either it lives in a person's head, or it does not exist anywhere today. Start here -- these rows are the real work.
B28: Where the sheet stands -- live counts, these update as you edit
B29: Measure | C29: What it tells us | D29: Count
B30: Rows in total | C30: 87 variables from the 19 Aug inventory, plus 1 flagged gap. Nothing dropped. | D30: =COUNTA('Master List'!$A$2:$A$94)
B31: Capacity Management | C31: Rows the workbook assigns to capacity. | D31: =COUNTIF('Master List'!$B$2:$B$94,"Capacity Management")
B32: Scheduling Engine | C32: Rows the workbook assigns to scheduling. | D32: =COUNTIF('Master List'!$B$2:$B$94,"Scheduling Engine")
B33: Engagement | C33: Rows the workbook assigns to engagement. | D33: =COUNTIF('Master List'!$B$2:$B$94,"Engagement")
B34: Shared across arenas | C34: Rows that also show up somewhere else — the seams. | D34: =COUNTIF('Master List'!$C$2:$C$94,"?*")
B35: Placement differs from the one-pager | C35: DECISION NEEDED. The workbook and the vendor page disagree on where these belong. | D35: =COUNTIF('Master List'!$E$2:$E$94,"Differs*")
B36: Low confidence on source | C36: START HERE. We do not know where this lives. | D36: =COUNTIF('Master List'!$K$2:$K$94,"Low")
B37: Medium confidence on source | C37: Right system, wrong-or-unknown screen. | D37: =COUNTIF('Master List'!$K$2:$K$94,"Medium")
B38: High confidence on source | C38: Settled. | D38: =COUNTIF('Master List'!$K$2:$K$94,"High")
B39: Nobody decides today | C39: No role reads the result. The clearest opportunities on the sheet. | D39: =COUNTIF('Master List'!$I$2:$I$94,"— no one*")
B40: Future state: Automate | C40: The tool does it end to end. | D40: =COUNTIF('Master List'!$L$2:$L$94,"Automate")
B41: Future state: Assist | C41: The tool proposes, a person confirms. | D41: =COUNTIF('Master List'!$L$2:$L$94,"Assist")
B42: Future state: Surface | C42: The tool shows, a person decides. | D42: =COUNTIF('Master List'!$L$2:$L$94,"Surface")
B43: Drifts — needs re-contact | C43: THE ENGAGEMENT LOAD. These go stale unless somebody keeps asking. | D43: =COUNTIF('Master List'!$O$2:$O$94,"Drifts*")
B44: ...and sitting outside Engagement | C44: Capacity and scheduling rows that still need an engagement mechanism under them. | D44: =COUNTIFS('Master List'!$O$2:$O$94,"Drifts*",'Master List'!$B$2:$B$94,"<>Engagement")
B45: ...caught in the day-before round | C45: The single recurring contact point the process already has. Today it is manual, every patient, every day. | D45: =COUNTIF('Master List'!$P$2:$P$94,"Day before*")
B46: ...caught in the weekly build | C46: The clinician's own weekly planning pass. | D46: =COUNTIF('Master List'!$P$2:$P$94,"Weekly*")
B47: ...with no re-check at all | C47: Drifts, and nothing catches it. Silent staleness. | D47: =COUNTIFS('Master List'!$O$2:$O$94,"Drifts*",'Master List'!$P$2:$P$94,"Not re-checked today")
...

Sheet Master List
A1: ID | B1: Arena (8.19 workbook) | C1: Also touches | D1: One-pager group | E1: Placement check | F1: Variable (workbook name) | G1: In plain terms | H1: Who does the work today | I1: Who reads it and decides today | J1: Where the information lives today | K1: Confidence | L1: Future state -- the tool's role | M1: Future state -- who decides | N1: Trigger / how often | O1: Stays true on its own? | P1: Re-checked when | Q1: MVP | R1: Gating | S1: Adoption sensitivity | T1: Why this posture / watch-out | U1: Open question for the team | V1: Constraint (8.13) | W1: Automation posture (8.13) | X1: Sourced by (8.13) | Y1: Current state (8.13) | Z1: Source of truth (8.13) | AA1: Measurability (8.13) | AB1: Automation confidence (8.13) | AC1: Rollup key (8.13) | AD1: Weight (8.13) | AE1: Conflict risk (8.13)
A2: SH-01 | B2: Capacity Management | C2: Scheduling | D2: Workforce supply | E2: Aligned | F2: Clinician headcount | G2: How many clinicians the branch actually has, counted by discipline. The base number every capacity answer starts from. | H2: HR / Talent — maintains the record | I2: Branch Leadership (ED) — at staffing and budget reviews | J2: Workday — worker record; mirrored into HCHB | K2: High | L2: Automate | M2: Branch Leadership (ED) — owns the exception when the two systems disagree | N2: Continuous — changes on hire/term | O2: Stable | P2: — | Q2: Yes | R2: Y | S2: Low | T2: A clean roster fact in a system of record. The only risk is Workday and HCHB disagreeing. | U2: Which system wins when Workday and HCHB disagree on who is active? | V2: Structural | W2: Control | X2: Branch | Y2: In-system | Z2: Workday + HCHB | AA2: Quantitative | AB2: High | AC2: SHD-A | AD2: 3 | AE2: N
A3: SH-02 | B3: Capacity Management | C3: Scheduling | D3: Workforce supply | E3: Aligned | F3: Discipline | G3: What licence each person holds — RN, LPN, PT, PTA, OT, COTA, SLP, MSW, aide. Capacity is always counted inside a discipline: an RN shortage cannot be covered by a spare PT. | H3: HR / Talent — maintains the record | I3: — no one reviews this today; it is simply read | J3: Workday — worker record; mirrored into HCHB | K3: High | L3: Automate | M3: — exception only | N3: Continuous — changes on hire/term | O3: Stable | P3: — | Q3: Yes | R3: Y | S3: Low | T3: Hard licensure fact, fully in the data. | U3: Are the discipline codes identical in Workday and HCHB, or do they need mapping? | V3: Structural | W3: Control | X3: Branch | Y3: In-system | Z3: Workday + HCHB | AA3: Quantitative | AB3: High | AC3: SHD-A | AD3: 3 | AE3: N
A4: SH-03 | B4: Capacity Management | C4: Scheduling | D4: Workforce supply | E4: Aligned | F4: Role — assessing vs assistant | G4: Whether a clinician can open and evaluate a case (RN, PT, OT, SLP) or only carry follow-up visits (LPN, PTA, COTA). This is the lever behind offloading routine visits so assessing staff are free for admissions. | H4: — derived from discipline, nobody maintains it separately | I4: Clinical Manager / DCS — when deciding what can be offloaded | J4: Derived from discipline | K4: High | L4: Automate | M4: Clinical Manager — owns offload policy | N4: Continuous — derived | O4: Live / computed | P4: — | Q4: Yes | R4: Y | S4: Medium | T4: Deterministic from discipline. The sensitivity is not the data, it is the change-management of moving work to assistants. | U4: Is the assessing/assistant split written down as policy anywhere, or only understood? | V4: Structural | W4: Control | X4: Branch | Y4: In-system | Z4: Derived | AA4: Quantitative | AB4: High | AC4: SHD-A | AD4: 3 | AE4: N
A5: SH-04 | B5: Capacity Management | D5: Workforce supply | E5: Aligned | F5: FTE and employment type | G5: Full-time, part-time, per-diem or contract — and the fraction of a full week each person is expected to work. Sets the ceiling of what any individual can carry. | H5: HR / Talent — maintains the record | I5: Branch Leadership (ED) — at staffing reviews | J5: Workday — worker record | K5: High | L5: Automate | M5: Branch Leadership (ED) | N5: Continuous — changes on status change | O5: Stable | P5: — | Q5: Yes | R5: Y | S5: Low | T5: Clean employment attribute. Flagged as a conflict risk: a vendor that models FTE differently will fight the branch. | U5: Do per-diem and contract clinicians carry an FTE value at all, or are they null? | V5: Structural | W5: Control | X5: Branch | Y5: In-system | Z5: Workday | AA5: Quantitative | AB5: High | AC5: SHD-A | AD5: 3 | AE5: Y
A6: C-01 | B6: Capacity Management | D6: Workforce supply | E6: Aligned | F6: Headcount by discipline and employment type | G6: The staffed supply cut both ways at once — how many RNs are full-time, how many are per-diem, and so on. The single largest driver of what a branch can deliver. | H6: HR / Talent — maintains the record | I6: Branch Leadership (ED) — at staffing and referral-acceptance decisions | J6: Workday — worker record, rolled up | K6: High | L6: Automate | M6: Branch Leadership (ED) | N6: Continuous | O6: Stable | P6: — | Q6: Yes | R6: Y | S6: Low | T6: A branch is only as capable as its thinnest discipline; this is the view that shows it. | U6: Who owns the branch roll-up today — is anyone producing this view at all? | V6: Structural | W6: Control | X6: Branch | Y6: In-system | Z6: Workday | AA6: Quantitative | AB6: High | AC6: CAP-A | AD6: 3 | AE6: Y
A7: C-09 | B7: Capacity Management | C7: Engagement | D7: Workforce supply | E7: Aligned | F7: Per-diem and float pool | G7: The flex staff a branch can call on when its core team is full. Per-diem and float clinicians deliberately have no territory — that is what makes them a targeted instrument, used either to absorb admissions or to free a territory clinician for coverage. | H7: Scheduler and DCS — work the per-diem list by call, text and Teams | I7: DCS — decides when to spend the float lever | J7: Stated availability lives with the scheduler — a list, a spreadsheet or memory. HCHB holds who they are, not what they will take. | K7: Low | L7: Surface | M7: DCS — decides who to ask and when | N7: On event — call-outs and admission spikes | O7: Drifts — needs re-contact | P7: Weekly — when the week is built | Q7: Yes | R7: Y | S7: High | T7: The size of the buffer is legible; whether it actually flexes is relational. The system can show who is available, never assume they will say yes. | U7: Is there a maintained per-diem availability list anywhere, or is it rebuilt from memory each time? | V7: Structural | W7: Assist | X7: Branch | Y7: Manual | Z7: Manual + HCHB | AA7: Quantitative | AB7: Medium | AC7: CAP-E | AD7: 3 | AE7: N
A8: C-10 | B8: Capacity Management | C8: Scheduling | D8: Workforce supply | E8: Aligned | F8: Specialty competency supply | G8: How many clinicians can perform the visits that need more than a licence — wound, IV and infusion, catheter, ventilator, paediatric. Fourteen RNs but only three wound-certified means wound capacity, not RN capacity, is the real constraint. | H8: — partly HR (formal certs), partly nobody (informal competency) | I8: Clinical Manager — knows who is genuinely capable | J8: Workday holds formal licences and certifications. Informal competency lives in the Clinical Manager's head. | K8: Low | L8: Surface | M8: Clinical Manager — confirms who is genuinely competent | N8: Slow-changing — on certification or experience | O8: Drifts — needs re-contact | P8: Not re-checked today | Q8: Maybe | R8: N | S8: Medium | T8: Competency lives partly in reputation, not credentials. Surfacing it is useful; scoring it is not. | U8: Is there a competency list per clinician anywhere today, and who would own keeping it current? | V8: Structural | W8: Assist | X8: Clinician | Y8: Tacit | Z8: Workday + Manual | AA8: Quantitative | AB8: Medium | AC8: CAP-F | AD8: 1 | AE8: N
A9: C-11 | B9: Capacity Management | D9: Workforce supply | E9: Aligned | F9: Orientation and ramp status | G9: New hires count as headcount long before they carry a full load. Ignoring the ramp overstates supply — a week-two hire is not a full clinician. | H9: HR / Talent — records hire date and orientation status | I9: Clinical Manager — judges when someone is genuinely at full load | J9: Workday — hire date and orientation status. The ramp curve itself is not recorded anywhere. | K9: Medium | L9: Assist | M9: Clinical Manager — confirms the real ramp position | N9: Weekly during onboarding | O9: Stable | P9: — | Q9: Maybe | R9: N | S9: Low | T9: Headcount is clear; the true ramp curve is judgment. A system can propose a curve, a manager corrects it. | U9: Is there a standard ramp expectation by discipline, or is it manager-by-manager? | V9: Structural | W9: Assist | X9: Branch | Y9: In-system | Z9: Workday | AA9: Quantitative | AB9: Medium | AC9: CAP-G | AD9: 1 | AE9: N
A10: C-12 | B10: Capacity Management | C10: Scheduling | D10: Workforce supply | E10: Aligned | F10: On-call and weekend rotation load | G10: Work carried outside the standard week. A clinician coming off a weekend rotation starts Monday already partly loaded — if the schedule ignores it, the week is over-packed from day one. | H10: Scheduler — maintains the rotation | I10: Clinical Manager — balances the rotation across the team | J10: HCHB — on-call / rotation schedule | K10: Medium | L10: Automate | M10: Clinical Manager — owns rotation fairness | N10: Weekly | O10: Stable | P10: — | Q10: Yes | R10: Y | S10: Medium | T10: Legible load once the rotation is recorded. The fairness question is human. | U10: Is the rotation kept in HCHB, or on a separate branch calendar? | V10: Structural | W10: Control | X10: System | Y10: In-system | Z10: HCHB | AA10: Quantitative | AB10: High | AC10: CAP-C | AD10: 3 | AE10: N
A11: S-12 | B11: Capacity Management | C11: Scheduling, Engagement | D11: Workforce supply | E11: Aligned | F11: Willingness to flex | G11: How readily an individual clinician bends their pattern when asked — takes the extra visit, covers outside their territory, moves a day. It is the variable that decides which soft rules can actually be bent under pressure. | H11: Scheduler and DCS — learn it by asking, over time | I11: Scheduler — decides who to ask first | J11: Nobody's system. It lives in the scheduler's and DCS's working knowledge of their team. | K11: Low | L11: Surface | M11: Scheduler / DCS — decide who to approach | N11: On event — coverage and surge | O11: Drifts — needs re-contact | P11: On event — coverage and surge | Q11: Maybe | R11: N | S11: High | T11: A purely relational variable: the act of automating it changes what it measures. Surface who has said yes before; never auto-assign on it. | U11: Would clinicians accept this being visible at all? This is a trust question before it is a data question. | V11: Soft | W11: Read | X11: Clinician | Y11: Tacit | Z11: Manual | AA11: Qualitative | AB11: Low | AC11: SCH-C | AD11: 1 | AE11: N
A12: S-13 | B12: Capacity Management | C12: Engagement | D12: Workforce supply | E12: Aligned | F12: Willingness to take extra visits or overtime | G12: Whether a clinician will go beyond target, and on what terms. Strongly tied to pay model — a per-visit clinician has a reason to say yes that a salaried one does not. | H12: Scheduler — asks, one clinician at a time | I12: Scheduler / DCS — decide who to approach for coverage | J12: Nobody's system. Pay model is in Workday; willingness is not recorded anywhere. | K12: Low | L12: Surface | M12: Scheduler / DCS | N12: On event — coverage and surge | O12: Drifts — needs re-contact | P12: On event — coverage and surge | Q12: Maybe | R12: N | S12: High | T12: Relational and pay-linked. This is the row that connects to the incentives idea in the one-pager: today there is no mechanism, only a phone call. | U12: If we attach an incentive to hard-to-fill visits, who sets it and who approves the spend? | V12: Soft | W12: Read | X12: Clinician | Y12: Tacit | Z12: Manual | AA12: Qualitative | AB12: Low | AC12: SCH-C | AD12: 1 | AE12: N
A13: SH-05 | B13: Capacity Management | C13: Scheduling | D13: Availability & reach | E13: Aligned | F13: Approved time off and working availability | G13: The days each clinician is not available, and the pattern they normally work. The cleanest shared fact in the whole model: it removes capacity and removes a schedulable slot at the same moment. | H13: Clinician requests it; HR / manager approves it | I13: Scheduler — works around it when building the week | J13: Workday — time-off record. NOTE: the Workday-to-HCHB integration is currently OFF, so availability is re-entered by hand in HCHB. | K13: High | L13: Automate | M13: Scheduler — owns the exception when it is late or missing | N13: Continuous — as requests are approved | O13: Stable | P13: — | Q13: Yes | R13: Y | S13: Low | T13: A firm blackout once it is in the field. The integration being off is the single highest-value plumbing fix on this sheet — it makes every capacity number stale. | U13: What would it take to turn the Workday-to-HCHB availability integration back on? | V13: Hard | W13: Control | X13: Clinician | Y13: In-system | Z13: Workday + HCHB | AA13: Quantitative | AB13: High | AC13: SHD-B | AD13: 3 | AE13: N
A14: SH-06 | B14: Capacity Management | C14: Scheduling | D14: Availability & reach | E14: Aligned | F14: Territory and service area | G14: Where the branch is responsible for covering, and which of that area each clinician works. Capacity in the wrong place is stranded capacity — it exists but cannot reach the patient. | H14: Branch Leadership and DCS — set the lines | I14: Branch Leadership (ED) — reviews alignment when capacity tightens | J14: HCHB holds branch coverage; clinician zip assignment is part HCHB, part local knowledge. | K14: Medium | L14: Assist | M14: Branch Leadership (ED) — approves any territory change | N14: Quarterly, or when capacity tightens | O14: Stable | P14: — | Q14: Yes | R14: Y | S14: Medium | T14: Territory lines look fixed but encode local knowledge and standing agreements. A tool should propose changes, never redraw them. | U14: Is the current zip-to-clinician assignment complete in HCHB, or does the scheduler hold part of it? | V14: Structural | W14: Assist | X14: Geography | Y14: Manual | Z14: HCHB + Manual + Census | AA14: Quantitative | AB14: Medium | AC14: SHD-C | AD14: 3 | AE14: Y
A15: C-02 | B15: Capacity Management | D15: Availability & reach | E15: Aligned | F15: Branch coverage territory | G15: The counties the branch has committed to serve. Sets the outer boundary — a gap here is a coverage hole no amount of scheduling can fill. | H15: Branch Leadership — sets it | I15: Branch Leadership (ED) — at growth and referral decisions | J15: HCHB — branch configuration | K15: High | L15: Automate | M15: Branch Leadership (ED) | N15: Config — set once, revisited rarely | O15: Stable | P15: — | Q15: Yes | R15: Y | S15: Low | T15: Fixed boundary, cleanly held in configuration. | U15: Does the recorded coverage area match what the branch actually accepts in practice? | V15: Structural | W15: Control | X15: Geography | Y15: In-system | Z15: HCHB | AA15: Quantitative | AB15: High | AC15: CAP-B | AD15: 3 | AE15: N
A16: C-03 | B16: Capacity Management | C16: Scheduling | D16: Availability & reach | E16: Aligned | F16: Clinician territory assignment | G16: Which zip codes each clinician covers. Territories were originally drawn on thin data and have stayed largely static, with no live relationship to where referrals are actually coming from — so capacity drifts away from demand quietly. | H16: DCS and Scheduler — assign and adjust | I16: Branch Leadership (ED) with DCS — at the joint review when capacity tightens | J16: HCHB holds the assignment where it has been entered; the working version is often the scheduler's own reference. | K16: Medium | L16: Assist | M16: Branch Leadership (ED) with DCS | N16: Quarterly, or on demand shift | O16: Stable | P16: — | Q16: Yes | R16: Y | S16: High | T16: Called out in the inventory as the initial variable in the whole equation. Pairing it with a live census heat-map is the highest-leverage capacity change identified. | U16: How current is the zip assignment in HCHB right now — and when was it last reviewed against referral patterns? | V16: Structural | W16: Assist | X16: Geography | Y16: Manual | Z16: HCHB + Manual | AA16: Quantitative | AB16: Medium | AC16: CAP-B | AD16: 3 | AE16: Y
A17: C-04 | B17: Capacity Management | D17: Availability & reach | E17: Aligned | F17: Census-tract precision | G17: Whether to model coverage at a finer grain than zip. One large zip can span an urban core and a rural edge with completely different drive times, so the zip average misleads in both directions. | H17: — not done today | I17: Initiative team — a modelling decision, not an operational one | J17: Not in any system. Census data is public; the decision is ours. | K17: Medium | L17: Assist | M17: Initiative team — decide once, deliberately | N17: One-time decision | O17: Stable | P17: — | Q17: Yes | R17: Y | S17: Low | T17: A modelling choice, not a live control. It reshapes both the capacity map and the routing at once, so it should be decided on purpose rather than inherited from a vendor default. | U17: Do we want to make this call before vendor selection, or let the shortlist show us what is practical? | V17: Config | W17: Assist | X17: Geography | Y17: In-system | Z17: Census | AA17: Quantitative | AB17: Medium | AC17: CAP-B | AD17: 3 | AE17: Y
A18: C-14 | B18: Capacity Management | C18: Scheduling | D18: Availability & reach | E18: Aligned | F18: Territory currency | G18: Whether the territories are still right. C-03 records what each territory is; this records whether it still matches where the patients actually are, and how far the two have drifted. The drift is invisible until capacity is stranded in one zip while the area next to it turns work away. | H18: — not done today | I18: Branch Leadership (ED) with DCS — at the joint review when capacity tightens | J18: Not captured. It would come from comparing the territory assignment in HCHB against actual caseload and referral distribution. | K18: Low | L18: Assist | M18: Branch Leadership (ED) — redrawing a boundary is a leadership act | N18: Quarterly | O18: Live / computed | P18: — | Q18: Yes | R18: Y | S18: Medium | T18: Added 19 Aug. The workbook's own example is the whole argument: one territory carrying about thirty patients across two full-time clinicians while the adjacent area declines starts. The tool proposes the misalignment; a person moves the boundary. | U18: What cadence do we want for territory review, and who convenes it?
A19: S-46 | B19: Capacity Management | C19: Scheduling | D19: Availability & reach | E19: Aligned | F19: Achievable first-visit time | G19: The earliest visit a clinician can actually secure, as distinct from the time they would like to start. Nothing records the gap between the two — and that gap is the clearest measure of a day lost to the caseload rather than to any decision anyone made. | H19: — not measured today | I19: — no one today | J19: Not captured. It has to be asked, not inferred. | K19: Low | L19: Surface | M19: Clinical Manager — owns the gap as a problem to work | N19: Weekly | O19: Drifts — needs re-contact | P19: Weekly — when the week is built | Q19: Maybe | R19: N | S19: High | T19: Added 19 Aug, and deliberately read-only. Inferring the preference from observed start times would record defeat as choice and then optimise to preserve it. Ask, record the answer, report the gap. | U19: Who asks, and how often? This only works if the answer is collected rather than derived.
A20: C-05 | B20: Capacity Management | C20: Scheduling | D20: The capacity math | E20: Aligned | F20: Committed load — points already booked | G20: How much work is already on each clinician's calendar, in points. Capacity means nothing until you net this off: open room is the ceiling minus what is already committed. | H20: — the system holds it; nobody maintains it | I20: Scheduler — reads it while assigning; Clinical Manager — at productivity reviews | J20: HCHB — derived from booked visits; read through the scheduling and productivity views. | K20: Medium | L20: Automate | M20: Clinical Manager — acts on the imbalance | N20: Daily | O20: Live / computed | P20: — | Q20: Yes | R20: N | S20: Low | T20: Derived and safe to compute. The catch is pending-auth visits, which are on no calendar and count toward nothing — so this number is already understated today. | U20: Confirm which HCHB view the branch actually uses for committed points, and whether pending-auth visits appear anywhere in it. | V20: Derived | W20: Control | X20: System | Y20: In-system | Z20: Derived | AA20: Quantitative | AB20: High | AC20: CAP-C | AD20: 3 | AE20: N
A21: C-06 | B21: Capacity Management | C21: Scheduling | D21: The capacity math | E21: Aligned | F21: Open room by day | G21: How many bookable points are left in each day once assigned work is subtracted. The operational read of capacity — green means space, red means the day is full. | H21: — not produced as a view today | I21: — no one systematically; the scheduler infers it while assigning | J21: Not produced today. It would be derived from committed load against the daily ceiling. | K21: Low | L21: Automate | M21: Scheduler — acts on it daily; Clinical Manager — on the pattern | N21: Daily | O21: Live / computed | P21: — | Q21: Yes | R21: Y | S21: Low | T21: Pure derivation, but only as good as the point definitions underneath it. This is one of the clearest 'nobody can see this today' rows. | U21: Does any current HCHB view show open points by day, or is this genuinely net-new? | V21: Derived | W21: Control | X21: System | Y21: In-system | Z21: Derived | AA21: Quantitative | AB21: High | AC21: CAP-D | AD21: 3 | AE21: Y
A22: C-07 | B22: Capacity Management | D22: The capacity math | E22: Aligned | F22: Open capacity for the rest of the week | G22: The 'how much more can we take this week' number — the one a branch leader actually acts on when deciding whether to accept a referral. | H22: — not produced as a view today | I22: Branch Leadership (ED) — would own the decision it feeds | J22: Not produced today. | K22: Low | L22: Automate | M22: Branch Leadership (ED) — referral acceptance | N22: Daily | O22: Live / computed | P22: — | Q22: Yes | R22: N | S22: Low | T22: The headline capacity number. Everything else on this sheet exists to make it trustworthy. | U22: What is the decision this number should drive, and who makes it — ED, DCS, or intake? | V22: Derived | W22: Control | X22: System | Y22: In-system | Z22: Derived | AA22: Quantitative | AB22: High | AC22: CAP-D | AD22: 3 | AE22: N
A23: C-08 | B23: Capacity Management | C23: Scheduling | D23: The capacity math | E23: Aligned | F23: Admission capacity by discipline | G23: Open capacity limited to the clinicians who can actually open a case. New patients can only be absorbed by assessing staff, so this — not total capacity — is what gates growth. | H23: — not produced as a view today | I23: Branch Leadership (ED) and DCS — at referral acceptance | J23: Not produced today. | K23: Low | L23: Automate | M23: Branch Leadership (ED) / DCS | N23: Daily | O23: Live / computed | P23: — | Q23: Yes | R23: Y | S23: Low | T23: The growth-gating number. Distinct from total open room and more binding. | U23: How does the branch decide today whether it can take another admission — what is the current proxy? | V23: Derived | W23: Control | X23: System | Y23: In-system | Z23: Derived | AA23: Quantitative | AB23: High | AC23: CAP-D | AD23: 3 | AE23: Y
A24: SH-07 | B24: Capacity Management | C24: Scheduling | D24: The capacity math | E24: Aligned | F24: Visit weighting — the point value of each visit type | G24: The shared currency. A start of care is worth more than a routine visit, so the same headcount delivers different capacity depending on the mix of work. Everything in capacity and productivity is denominated in these points. | H24: Corporate / Operations — sets the values | I24: Clinical Manager and Branch Leadership — read productivity against them | J24: HCHB holds point values per visit type; the surrounding policy sits in branch and corporate configuration. | K24: Medium | L24: Automate | M24: Corporate / Operations — owns the definition | N24: Config — set once, revisited by policy | O24: Stable | P24: — | Q24: Yes | R24: N | S24: Medium | T24: The values exist. What is undefined is how travel, documentation time and acuity are treated — and until that is settled, every derived capacity number inherits the ambiguity. | U24: Open question #1: do points account for travel, documentation and acuity, or only visit type? | V24: Config | W24: Control | X24: System | Y24: In-system | Z24: Config | AA24: Quantitative | AB24: High | AC24: SHD-D | AD24: 3 | AE24: Y
A25: SH-08 | B25: Capacity Management | D25: The capacity math | E25: Aligned | F25: Targets and ceilings | G25: The weekly load a clinician is expected to carry and the daily maximum they should not exceed. The target is what we plan toward; the ceiling is what capacity cannot cross. | H25: Corporate / Operations — sets it | I25: Clinical Manager — manages individuals against it | J25: HCHB productivity settings plus branch policy. | K25: Medium | L25: Automate | M25: Clinical Manager | N25: Config | O25: Stable | P25: — | Q25: Yes | R25: N | S25: Medium | T25: A policy constant and a simple lookup. Conflict risk: a vendor with its own opinion about targets will fight branch policy. | U25: Are targets uniform across branches and disciplines, or do they vary? | V25: Config | W25: Control | X25: Branch | Y25: In-system | Z25: HCHB + Config | AA25: Quantitative | AB25: High | AC25: SHD-E | AD25: 3 | AE25: Y
A26: SH-09 | B26: Capacity Management | C26: Scheduling | D26: The capacity math | E26: Aligned | F26: Referrals coming in, discharges going out | G26: The two events that move the envelope. A referral consumes capacity when it is assigned; a discharge hands it back. Reading them together is how you see capacity as a shape over the next few weeks rather than a number today. | H26: Intake — receives referrals; Clinician — performs the discharge | I26: Branch Leadership (ED) — reads the balance | J26: Referrals arrive in Commure and land in HCHB; discharges are in HCHB. | K26: Medium | L26: Automate | M26: Branch Leadership (ED) | N26: Continuous — as events occur | O26: Stable | P26: — | Q26: Yes | R26: N | S26: Low | T26: Detecting the events is straightforward. What to do about the trend is the judgment, and it sits with the branch. | U26: Is discharge date reliable enough in HCHB to forecast returning capacity? | V26: Event | W26: Control | X26: System | Y26: In-system | Z26: HCHB | AA26: Quantitative | AB26: High | AC26: SHD-F | AD26: 3 | AE26: N
A27: C-13 | B27: Capacity Management | D27: The capacity math | E27: Aligned | F27: Referral volume (held out of scope) | G27: The rate of incoming referrals. Recorded here for completeness and deliberately not treated as a lever in this initiative — it belongs to intake and growth, not to capacity and scheduling. | H27: Intake — receives them | I27: Growth / Branch Leadership — outside this initiative | J27: Commure and HCHB. | K27: Medium | L27: Stays manual | M27: — outside this initiative | N27: Continuous | O27: Stable | P27: — | Q27: No | R27: N | S27: Low | T27: Out of scope by choice, documented so the capacity math is transparent about what it holds constant. | U27: Confirm this stays out of scope as the initiative moves into future-state design. | V27: Context | W27: Read | X27: System | Y27: In-system | Z27: HCHB | AA27: Quantitative | AB27: Low | AC27: CAP-H | AD27: 0 | AE27: N
A28: S-04 | B28: Capacity Management | C28: Capacity | D28: Matching | E28: Differs — the one-pager groups this under Scheduling Engine | F28: Preferred working days | G28: The days each clinician normally works, including rotations like four long days or a standing Friday off. Baseline availability that scheduling has to respect. | H28: Clinician — states it; Scheduler — holds it | I28: Scheduler | J28: Partly HCHB, partly the scheduler's own knowledge. Rotations and swaps are handled informally. | K28: Low | L28: Assist | M28: Scheduler | N28: Slow-changing, with informal exceptions | O28: Drifts — needs re-contact | P28: Weekly — when the week is built | Q28: Maybe | R28: N | S28: Medium | T28: A set pattern with informal exceptions — the exceptions are the part no system holds. | U28: Are working patterns recorded in HCHB per clinician, or reconstructed by the scheduler each week? | V28: Soft | W28: Assist | X28: Clinician | Y28: Tacit | Z28: Manual + HCHB | AA28: Qualitative | AB28: Medium | AC28: SCH-C | AD28: 1 | AE28: N
A29: S-05 | B29: Capacity Management | D29: Matching | E29: Differs — the one-pager groups this under Scheduling Engine | F29: Preferred start time | G29: When a clinician likes to begin. It anchors the front of the route, and the first visit of the day is the single largest lever on an individual's capacity — an 8am start and a 10am start are very different days. | H29: Clinician — states it | I29: Scheduler — decides how far to accommodate | J29: Nobody's system — the scheduler's working knowledge. | K29: Low | L29: Assist | M29: Scheduler | N29: Daily, in practice | O29: Drifts — needs re-contact | P29: Weekly — when the week is built | Q29: Maybe | R29: N | S29: High | T29: Preferred and possible are two different things. Many clinicians want an early first visit and struggle to make it happen; it takes planning and patient motivation, not just a preference field. | U29: Do we want to set a branch expectation on first-visit time, or keep it individual? | V29: Soft | W29: Assist | X29: Clinician | Y29: Tacit | Z29: Manual | AA29: Qualitative | AB29: Medium | AC29: SCH-C | AD29: 1 | AE29: N
A30: S-06 | B30: Capacity Management | D30: Matching | E30: Differs — the one-pager groups this under Scheduling Engine | F30: Start-time flexibility | G30: Whether that start time can move day to day. It separates a clinician who will shift to fit a patient window from one who cannot — which is a real scheduling lever, but only if they have told you. | H30: Clinician — decides in the moment | I30: Scheduler — asks | J30: Nobody's system. | K30: Low | L30: Surface | M30: Scheduler | N30: Daily | O30: Drifts — needs re-contact | P30: Day before — the confirmation round | Q30: Maybe | R30: N | S30: High | T30: Depends on a person's willingness. Assuming it is available damages the trust the whole thing runs on — surface only. | U30: None — this row is intentionally read-only. | V30: Soft | W30: Read | X30: Clinician | Y30: Tacit | Z30: Manual | AA30: Qualitative | AB30: Low | AC30: SCH-C | AD30: 1 | AE30: N
A31: S-07 | B31: Capacity Management | D31: Matching | E31: Differs — the one-pager groups this under Scheduling Engine | F31: Lunch and documentation pattern | G31: Whether a clinician holds time mid-day for a break or for charting. It removes a slot and splits the route into two halves. | H31: Clinician — their own habit | I31: Scheduler — builds around it | J31: Nobody's system. | K31: Low | L31: Assist | M31: Scheduler | N31: Daily | O31: Drifts — needs re-contact | P31: Weekly — when the week is built | Q31: Maybe | R31: N | S31: Medium | T31: A capturable personal habit. Worth knowing, not worth enforcing. | U31: Would clinicians be willing to record this, or does it feel like surveillance? | V31: Soft | W31: Assist | X31: Clinician | Y31: Tacit | Z31: Manual | AA31: Qualitative | AB31: Medium | AC31: SCH-C | AD31: 1 | AE31: N
A32: S-08 | B32: Capacity Management | D32: Matching | E32: Differs — the one-pager groups this under Scheduling Engine | F32: Mid-day documentation block | G32: Time reserved specifically for charting, usually mid-afternoon. It consumes schedulable time and shapes the day into segments. | H32: Clinician — their own habit | I32: Scheduler — builds around it | J32: Nobody's system. | K32: Low | L32: Assist | M32: Scheduler | N32: Daily | O32: Drifts — needs re-contact | P32: Weekly — when the week is built | Q32: Maybe | R32: N | S32: Medium | T32: Same shape as the lunch pattern. Note that documentation time is real capacity consumed, and today it is invisible in the point math. | U32: Should documentation time be represented in the point system? Ties to open question #1. | V32: Soft | W32: Assist | X32: Clinician | Y32: Tacit | Z32: Manual | AA32: Qualitative | AB32: Medium | AC32: SCH-C | AD32: 1 | AE32: N
A33: S-09 | B33: Capacity Management | D33: Matching | E33: Differs — the one-pager groups this under Scheduling Engine | F33: Split shift or mid-day personal break | G33: A gap in the middle of the day — school pickup, an errand — with visits either side. It creates a two-cluster day rather than a continuous one. | H33: Clinician — their own routine | I33: Scheduler — builds around it when told | J33: Nobody's system. | K33: Low | L33: Surface | M33: Scheduler | N33: Daily, and it varies | O33: Drifts — needs re-contact | P33: Day before — the confirmation round | Q33: Maybe | R33: N | S33: High | T33: A personal daily rhythm that varies. Hard to predict reliably and easily disrupted by a system that assumes it knows — read only. | U33: None — intentionally read-only. | V33: Soft | W33: Read | X33: Clinician | Y33: Tacit | Z33: Manual | AA33: Qualitative | AB33: Low | AC33: SCH-C | AD33: 1 | AE33: N
A34: S-10 | B34: Capacity Management | D34: Matching | E34: Differs — the one-pager groups this under Scheduling Engine | F34: Hard stop — when the day has to end | G34: The time a clinician must be finished by, usually for childcare or a second commitment. Once you know it, it behaves exactly like a hard rule; the difficulty is that knowing it depends on them telling you. | H34: Clinician — states it | I34: Scheduler — honours it | J34: Nobody's system. | K34: Low | L34: Assist | M34: Scheduler | N34: Daily | O34: Drifts — needs re-contact | P34: Weekly — when the week is built | Q34: Yes | R34: N | S34: Medium | T34: A firm edge once known. The knowing is the tacit part. | U34: Is there a place a clinician could record a standing hard stop today? | V34: Hard/Soft | W34: Assist | X34: Clinician | Y34: Tacit | Z34: Manual | AA34: Qualitative | AB34: Medium | AC34: SCH-C | AD34: 3 | AE34: N
A35: S-11 | B35: Capacity Management | D35: Matching | E35: Differs — the one-pager groups this under Scheduling Engine | F35: Maximum visits in a day | G35: The most visits an individual will carry before the day stops working, regardless of what the points allow. It bounds how densely a day can be packed. | H35: Clinician — states it | I35: Scheduler — respects it | J35: Nobody's system. | K35: Low | L35: Assist | M35: Scheduler | N35: Slow-changing | O35: Drifts — needs re-contact | P35: Weekly — when the week is built | Q35: Maybe | R35: N | S35: Medium | T35: A personal ceiling, capturable and worth confirming. Conflict risk: a vendor that packs to points alone will breach it. | U35: Do we want a branch-level maximum as well as an individual one? | V35: Soft | W35: Assist | X35: Clinician | Y35: Tacit | Z35: Manual | AA35: Qualitative | AB35: Medium | AC35: SCH-C | AD35: 1 | AE35: Y
A36: S-14 | B36: Scheduling Engine | C36: Scheduling | D36: Availability & reach | E36: Differs — the one-pager groups this under Capacity Management | F36: Home base — where the day starts and ends | G36: The point each clinician drives from and returns to. A first visit far from home wastes the front of the day, which is the most productive part of it. | H36: — captured informally, if at all | I36: Scheduler and Clinician — when building the route | J36: Home address is in Workday. Whether it is usable for drive-time is unconfirmed; routing today works off manual knowledge. | K36: Low | L36: Automate | M36: Scheduler — confirms the anchor | N36: Slow-changing | O36: Stable | P36: — | Q36: Yes | R36: Y | S36: Medium | T36: A legible anchor once captured. Using home addresses for routing has a privacy dimension worth settling early. | U36: Can we use clinician home addresses for drive-time calculation, and has that been agreed with them? | V36: Structural | W36: Control | X36: Geography | Y36: Manual | Z36: Manual + Routing | AA36: Quantitative | AB36: High | AC36: SCH-D | AD36: 3 | AE36: N
A37: S-01 | B37: Scheduling Engine | D37: Demand | E37: Aligned | F37: Ordered visits and frequency | G37: What each discipline has ordered for a patient and how often — the demand signal at the visit level. Everything scheduling does is placing these orders into slots that work. | H37: Clinician — plots the frequency in the plan of care; DCS — approves it | I37: DCS — approves the plan of care before anything can be scheduled | J37: HCHB — plan of care and generated visits | K37: High | L37: Automate | M37: DCS — owns plan-of-care approval | N37: Per episode, at plan of care and at each recertification | O37: Stable | P37: — | Q37: Yes | R37: Y | S37: Low | T37: Clear in HCHB. Note that each discipline plots to clinical need without seeing payer limits at that moment — which is where the auth collision starts. | U37: Nothing outstanding — this row is solid. | V37: Hard | W37: Control | X37: Patient | Y37: In-system | Z37: HCHB | AA37: Quantitative | AB37: High | AC37: SCH-A | AD37: 3 | AE37: N
A38: S-02 | B38: Scheduling Engine | D38: Demand | E38: Aligned | F38: Visit type | G38: What kind of visit each one is — start of care, routine, recertification, resumption, discharge, supervisory. It sizes the slot and dictates who is allowed to perform it. | H38: — set by the order | I38: Scheduler — reads it when assigning | J38: HCHB — visit record | K38: High | L38: Automate | M38: — exception only | N38: Per visit | O38: Stable | P38: — | Q38: Yes | R38: Y | S38: Low | T38: Clean order attribute. | U38: Nothing outstanding. | V38: Hard | W38: Control | X38: Patient | Y38: In-system | Z38: HCHB | AA38: Quantitative | AB38: High | AC38: SCH-A | AD38: 3 | AE38: N
A39: S-43 | B39: Scheduling Engine | C39: Capacity | D39: Demand | E39: Aligned | F39: Insurance authorization | G39: Whether the payer has agreed to pay for the visits, and how many. It behaves two completely different ways: at admission it is a gate — nothing schedules until it clears — and inside the episode it is a silent ceiling checked visit by visit. | H39: Auth team — verifies eligibility and keys the pending auth; Intake — gives final approval | I39: Auth team, then Intake — and the Scheduler holds what is stuck | J39: HCHB holds auth status per visit; the referral side sits in Commure. The payer's actual rules are written by the auth team into a coordination note at verification — days before anyone writes the plan of care. | K39: Medium | L39: Automate | M39: Scheduler — owns what falls out; Auth team — owns the exception | N39: Per episode and per add-on order | O39: Stable | P39: — | Q39: Yes | R39: Y | S39: Medium | T39: The largest single bottleneck in current-state scheduling, and the most tractable: the rules already exist in writing before they are needed. Surfacing the coordination note at plan-of-care creation is the highest-value, lowest-complexity win identified. Pending-auth visits sit on no calendar and count toward nothing — if you cannot see it, you cannot plan it. | U39: Can the auth coordination note be surfaced into the plan-of-care screen, and who owns that change?
A40: S-44 | B40: Scheduling Engine | C40: Capacity | D40: Demand | E40: Aligned | F40: Add-on orders | G40: Any order written after the plan of care is submitted. In steady state there is no recurring scheduler workflow at all unless an add-on changes the frequency — at which point it routes through DCS approval, then authorization, then back to the scheduler, for every affected discipline. | H40: Clinician — requests; DCS — reviews | I40: DCS — decides, then it returns to the auth loop | J40: HCHB — orders. The DCS review workflow itself is described as still being defined. | K40: Low | L40: Assist | M40: DCS | N40: On event — mid-episode | O40: Stable | P40: — | Q40: Yes | R40: Y | S40: Medium | T40: Flagged in the inventory as a bottleneck awaiting DCS workflow. It affects how capacity looks as well as what gets scheduled. | U40: What is the current DCS add-on workflow, and is it consistent across branches?
...

Sheet Lists
A1: Arena (8.19 workbook) | B1: Confidence | C1: Future state -- the tool's role | D1: Adoption sensitivity | E1: MVP | F1: Gating | G1: Trigger / how often | H1: Roles (for the two owner columns) | I1: Stays true on its own? | J1: Re-checked when
A2: Capacity Management | B2: High | C2: Automate | D2: High | E2: Yes | F2: Y | G2: Per referral | H2: Intake | I2: Stable | J2: At referral / welcome call
A3: Scheduling Engine | B3: Medium | C3: Assist | D3: Medium | E3: Maybe | F3: N | G3: Per episode | H3: Auth team | I3: Drifts — needs re-contact | J3: At start of care
A4: Engagement | B4: Low | C4: Surface | D4: Low | E4: No | G4: Per visit | H4: Scheduler | I4: Live / computed | J4: Weekly — when the week is built
C5: Stays manual | E5: -- | G5: Daily | H5: DCS | I5: This is the contact | J5: Day before — the confirmation round
G6: Day before the visit | H6: Clinician | J6: At recertification
G7: Weekly | H7: Clinical Manager | J7: On event — coverage and surge
G8: Quarterly | H8: Branch Leadership (ED) | J8: Not re-checked today
G9: On event | H9: Per Diem / Float | J9: —
G10: Continuous | H10: Case Manager
G11: Config | H11: HR / Talent
G12: Slow-changing | H12: Corporate / Operations
G13: One-time decision | H13: Patient / Caregiver
H14: -- no one today

Sheet Roles
B1: Roles, and the colours they carry on the current-state flow maps
B2: Use these names in the two owner columns. Keeping the vocabulary identical is what lets the future-state maps be drawn straight from this workbook.
B4: Role | C4: Colour | D4: What they do | E4: When they appear
B5: Intake | C5: #1F6F78 | D5: Receives the referral in Commure, and gives the final approval that releases it for scheduling. | E5: Admission
B6: Auth team | C6: #DF751D | D6: Verifies eligibility and keys the pending authorisation. Writes the payer's rules into a coordination note at verification — days before the plan of care is written. | E6: Admission, and every add-on, recert and resumption
B7: Scheduler (PCC) | C7: #C6A01F | D7: Makes the welcome call, books the start of care and evals, assigns every visit the frequency generates in one pass, and works the exception queues. Largely an administrator — the welcome call is the one real judgment call. | E7: Throughout
B8: DCS | C8: #792E2E | D8: Reviews the referral, approves the plan of care, owns add-on workflow, and shares call-out coverage with the scheduler. Escalation point for missed compliance. | E8: Throughout
B9: Clinician | C9: #2E599D | D9: Performs the visits, plots their own discipline's frequency, builds and confirms their own week after the plan of care, and selects the disposition the day before. | E9: Throughout
B10: Clinical Manager | C10: #2E599D | D10: Manages individuals against productivity, competency and ramp. The role that reads most of the reports on this sheet. | E10: Weekly and monthly
B11: Branch Leadership (ED) | C11: #1A1A1A | D11: One home in the current-state maps: the joint review pulled when capacity tightens — territory alignment and referral acceptance. | E11: When capacity tightens
B12: Per Diem / Float | C12: #795933 | D12: No territory, on purpose. A targeted instrument — take the admissions, or take coverage visits to free a territory clinician. | E12: On event
B13: HCHB | C13: #795CA7 | D13: The system acting by itself: generating tasks, applying rules, checking authorisation, suggesting a route. A workflow in HCHB worked by a person carries that person's colour, not this one. | E13: Continuous
