Workbook

Sheet Score Entry
B2: COMPASSUS · HOME HEALTH
B3: Capacity & Scheduling — Vendor Scorecard
B4: Rubric v1.0 · 41 spec elements · questionnaire form_version 2026-08-19. Score in the white cells only — every grey cell is a formula.
B6: VENDOR | D6: Vendor 01 | E6: Vendor 02 | F6: Vendor 03 | G6: Vendor 04 | H6: Vendor 05 | I6: Vendor 06 | J6: Vendor 07 | K6: Vendor 08 | L6: Vendor 09 | M6: Vendor 10 | N6: Vendor 11 | O6: Vendor 12 | P6: Vendor 13 | Q6: Vendor 14 | R6: Vendor 15 | S6: Vendor 16
B8: SCORE
B9: 1 · HCHB Integration | C9: of 25 | D9: =IFERROR(MIN(VLOOKUP(D23,Lists!$B$2:$C$7,2,FALSE),IF(D24="No",20,25)),0) | E9: =IFERROR(MIN(VLOOKUP(E23,Lists!$B$2:$C$7,2,FALSE),IF(E24="No",20,25)),0) | F9: =IFERROR(MIN(VLOOKUP(F23,Lists!$B$2:$C$7,2,FALSE),IF(F24="No",20,25)),0) | G9: =IFERROR(MIN(VLOOKUP(G23,Lists!$B$2:$C$7,2,FALSE),IF(G24="No",20,25)),0) | H9: =IFERROR(MIN(VLOOKUP(H23,Lists!$B$2:$C$7,2,FALSE),IF(H24="No",20,25)),0) | I9: =IFERROR(MIN(VLOOKUP(I23,Lists!$B$2:$C$7,2,FALSE),IF(I24="No",20,25)),0) | J9: =IFERROR(MIN(VLOOKUP(J23,Lists!$B$2:$C$7,2,FALSE),IF(J24="No",20,25)),0) | K9: =IFERROR(MIN(VLOOKUP(K23,Lists!$B$2:$C$7,2,FALSE),IF(K24="No",20,25)),0) | ... S9: =IFERROR(MIN(VLOOKUP(S23,Lists!$B$2:$C$7,2,FALSE),IF(S24="No",20,25)),0)
B10: 2 · Scope Footprint | C10: of 30 | D10: =D18*10+D19*10+D20*10 | E10: =E18*10+E19*10+E20*10 | F10: =F18*10+F19*10+F20*10 | G10: =G18*10+G19*10+G20*10 | H10: =H18*10+H19*10+H20*10 | I10: =I18*10+I19*10+I20*10 | J10: =J18*10+J19*10+J20*10 | K10: =K18*10+K19*10+K20*10 | ... S10: =S18*10+S19*10+S20*10
B11: 3 · Sophistication | C11: of 20 | D11: =(IFERROR(VALUE(LEFT(D87,1)),0)+IFERROR(VALUE(LEFT(D88,1)),0)+IFERROR(VALUE(LEFT(D89,1)),0)+IFERROR(VALUE(LEFT(D90,1)),0)+IFERROR(VALUE(LEFT(D91,1)),0))/20*20 | E11: =(IFERROR(VALUE(LEFT(E87,1)),0)+IFERROR(VALUE(LEFT(E88,1)),0)+IFERROR(VALUE(LEFT(E89,1)),0)+IFERROR(VALUE(LEFT(E90,1)),0)+IFERROR(VALUE(LEFT(E91,1)),0))/20*20 | F11: =(IFERROR(VALUE(LEFT(F87,1)),0)+IFERROR(VALUE(LEFT(F88,1)),0)+IFERROR(VALUE(LEFT(F89,1)),0)+IFERROR(VALUE(LEFT(F90,1)),0)+IFERROR(VALUE(LEFT(F91,1)),0))/20*20 | G11: =(IFERROR(VALUE(LEFT(G87,1)),0)+IFERROR(VALUE(LEFT(G88,1)),0)+IFERROR(VALUE(LEFT(G89,1)),0)+IFERROR(VALUE(LEFT(G90,1)),0)+IFERROR(VALUE(LEFT(G91,1)),0))/20*20 | H11: =(IFERROR(VALUE(LEFT(H87,1)),0)+IFERROR(VALUE(LEFT(H88,1)),0)+IFERROR(VALUE(LEFT(H89,1)),0)+IFERROR(VALUE(LEFT(H90,1)),0)+IFERROR(VALUE(LEFT(H91,1)),0))/20*20 | I11: =(IFERROR(VALUE(LEFT(I87,1)),0)+IFERROR(VALUE(LEFT(I88,1)),0)+IFERROR(VALUE(LEFT(I89,1)),0)+IFERROR(VALUE(LEFT(I90,1)),0)+IFERROR(VALUE(LEFT(I91,1)),0))/20*20 | J11: =(IFERROR(VALUE(LEFT(J87,1)),0)+IFERROR(VALUE(LEFT(J88,1)),0)+IFERROR(VALUE(LEFT(J89,1)),0)+IFERROR(VALUE(LEFT(J90,1)),0)+IFERROR(VALUE(LEFT(J91,1)),0))/20*20 | K11: =(IFERROR(VALUE(LEFT(K87,1)),0)+IFERROR(VALUE(LEFT(K88,1)),0)+IFERROR(VALUE(LEFT(K89,1)),0)+IFERROR(VALUE(LEFT(K90,1)),0)+IFERROR(VALUE(LEFT(K91,1)),0))/20*20 | ... S11: =(IFERROR(VALUE(LEFT(S87,1)),0)+IFERROR(VALUE(LEFT(S88,1)),0)+IFERROR(VALUE(LEFT(S89,1)),0)+IFERROR(VALUE(LEFT(S90,1)),0)+IFERROR(VALUE(LEFT(S91,1)),0))/20*20
B12: 4 · Clinician & Adoption | C12: of 10 | D12: =(IFERROR(VALUE(LEFT(D94,1)),0)+IFERROR(VALUE(LEFT(D95,1)),0)+IFERROR(VALUE(LEFT(D96,1)),0))/12*10 | E12: =(IFERROR(VALUE(LEFT(E94,1)),0)+IFERROR(VALUE(LEFT(E95,1)),0)+IFERROR(VALUE(LEFT(E96,1)),0))/12*10 | F12: =(IFERROR(VALUE(LEFT(F94,1)),0)+IFERROR(VALUE(LEFT(F95,1)),0)+IFERROR(VALUE(LEFT(F96,1)),0))/12*10 | G12: =(IFERROR(VALUE(LEFT(G94,1)),0)+IFERROR(VALUE(LEFT(G95,1)),0)+IFERROR(VALUE(LEFT(G96,1)),0))/12*10 | H12: =(IFERROR(VALUE(LEFT(H94,1)),0)+IFERROR(VALUE(LEFT(H95,1)),0)+IFERROR(VALUE(LEFT(H96,1)),0))/12*10 | I12: =(IFERROR(VALUE(LEFT(I94,1)),0)+IFERROR(VALUE(LEFT(I95,1)),0)+IFERROR(VALUE(LEFT(I96,1)),0))/12*10 | J12: =(IFERROR(VALUE(LEFT(J94,1)),0)+IFERROR(VALUE(LEFT(J95,1)),0)+IFERROR(VALUE(LEFT(J96,1)),0))/12*10 | K12: =(IFERROR(VALUE(LEFT(K94,1)),0)+IFERROR(VALUE(LEFT(K95,1)),0)+IFERROR(VALUE(LEFT(K96,1)),0))/12*10 | ... S12: =(IFERROR(VALUE(LEFT(S94,1)),0)+IFERROR(VALUE(LEFT(S95,1)),0)+IFERROR(VALUE(LEFT(S96,1)),0))/12*10
B13: 5 · Partnership | C13: of 15 | D13: =(IFERROR(VALUE(LEFT(D99,1)),0)+IFERROR(VALUE(LEFT(D100,1)),0)+IFERROR(VALUE(LEFT(D101,1)),0)+IFERROR(VALUE(LEFT(D102,1)),0))/16*15 | E13: =(IFERROR(VALUE(LEFT(E99,1)),0)+IFERROR(VALUE(LEFT(E100,1)),0)+IFERROR(VALUE(LEFT(E101,1)),0)+IFERROR(VALUE(LEFT(E102,1)),0))/16*15 | F13: =(IFERROR(VALUE(LEFT(F99,1)),0)+IFERROR(VALUE(LEFT(F100,1)),0)+IFERROR(VALUE(LEFT(F101,1)),0)+IFERROR(VALUE(LEFT(F102,1)),0))/16*15 | G13: =(IFERROR(VALUE(LEFT(G99,1)),0)+IFERROR(VALUE(LEFT(G100,1)),0)+IFERROR(VALUE(LEFT(G101,1)),0)+IFERROR(VALUE(LEFT(G102,1)),0))/16*15 | H13: =(IFERROR(VALUE(LEFT(H99,1)),0)+IFERROR(VALUE(LEFT(H100,1)),0)+IFERROR(VALUE(LEFT(H101,1)),0)+IFERROR(VALUE(LEFT(H102,1)),0))/16*15 | I13: =(IFERROR(VALUE(LEFT(I99,1)),0)+IFERROR(VALUE(LEFT(I100,1)),0)+IFERROR(VALUE(LEFT(I101,1)),0)+IFERROR(VALUE(LEFT(I102,1)),0))/16*15 | J13: =(IFERROR(VALUE(LEFT(J99,1)),0)+IFERROR(VALUE(LEFT(J100,1)),0)+IFERROR(VALUE(LEFT(J101,1)),0)+IFERROR(VALUE(LEFT(J102,1)),0))/16*15 | K13: =(IFERROR(VALUE(LEFT(K99,1)),0)+IFERROR(VALUE(LEFT(K100,1)),0)+IFERROR(VALUE(LEFT(K101,1)),0)+IFERROR(VALUE(LEFT(K102,1)),0))/16*15 | ... S13: =(IFERROR(VALUE(LEFT(S99,1)),0)+IFERROR(VALUE(LEFT(S100,1)),0)+IFERROR(VALUE(LEFT(S101,1)),0)+IFERROR(VALUE(LEFT(S102,1)),0))/16*15
B14: TOTAL | C14: of 100 | D14: =D9+D10+D11+D12+D13 | E14: =E9+E10+E11+E12+E13 | F14: =F9+F10+F11+F12+F13 | G14: =G9+G10+G11+G12+G13 | H14: =H9+H10+H11+H12+H13 | I14: =I9+I10+I11+I12+I13 | J14: =J9+J10+J11+J12+J13 | K14: =K9+K10+K11+K12+K13 | ... S14: =S9+S10+S11+S12+S13
B15: Band | C15: 80 / 65 / 50 | D15: =IF(D9<12,"Conditional — ","")&IF(D14>=80,"Advance",IF(D14>=65,"Consider",IF(D14>=50,"Hold","Decline"))) | E15: =IF(E9<12,"Conditional — ","")&IF(E14>=80,"Advance",IF(E14>=65,"Consider",IF(E14>=50,"Hold","Decline"))) | F15: =IF(F9<12,"Conditional — ","")&IF(F14>=80,"Advance",IF(F14>=65,"Consider",IF(F14>=50,"Hold","Decline"))) | G15: =IF(G9<12,"Conditional — ","")&IF(G14>=80,"Advance",IF(G14>=65,"Consider",IF(G14>=50,"Hold","Decline"))) | H15: =IF(H9<12,"Conditional — ","")&IF(H14>=80,"Advance",IF(H14>=65,"Consider",IF(H14>=50,"Hold","Decline"))) | I15: =IF(I9<12,"Conditional — ","")&IF(I14>=80,"Advance",IF(I14>=65,"Consider",IF(I14>=50,"Hold","Decline"))) | J15: =IF(J9<12,"Conditional — ","")&IF(J14>=80,"Advance",IF(J14>=65,"Consider",IF(J14>=50,"Hold","Decline"))) | K15: =IF(K9<12,"Conditional — ","")&IF(K14>=80,"Advance",IF(K14>=65,"Consider",IF(K14>=50,"Hold","Decline"))) | ... S15: =IF(S9<12,"Conditional — ","")&IF(S14>=80,"Advance",IF(S14>=65,"Consider",IF(S14>=50,"Hold","Decline")))
B17: Footprint — overall | D17: =(D18*11+D19*14+D20*16)/41 | E17: =(E18*11+E19*14+E20*16)/41 | F17: =(F18*11+F19*14+F20*16)/41 | G17: =(G18*11+G19*14+G20*16)/41 | H17: =(H18*11+H19*14+H20*16)/41 | I17: =(I18*11+I19*14+I20*16)/41 | J17: =(J18*11+J19*14+J20*16)/41 | K17: =(K18*11+K19*14+K20*16)/41 | ... S17: =(S18*11+S19*14+S20*16)/41
B18: Capacity Management | D18: =(IF(D29="Covered",1,IF(D29="Partial",0.5,0))+IF(D30="Covered",1,IF(D30="Partial",0.5,0))+IF(D31="Covered",1,IF(D31="Partial",0.5,0))+IF(D32="Covered",1,IF(D32="Partial",0.5,0))+IF(D33="Covered",1,IF(D33="Partial",0.5,0))+IF(D35="Covered",1,IF(D35="Partial",0.5,0))+IF(D36="Covered",1,IF(D36="Partial",0.5,0))+IF(D37="Covered",1,IF(D37="Partial",0.5,0))+IF(D39="Covered",1,IF(D39="Partial",0.5,0))+IF(D40="Covered",1,IF(D40="Partial",0.5,0))+IF(D41="Covered",1,IF(D41="Partial",0.5,0)))/11 | E18: =(IF(E29="Covered",1,IF(E29="Partial",0.5,0))+IF(E30="Covered",1,IF(E30="Partial",0.5,0))+IF(E31="Covered",1,IF(E31="Partial",0.5,0))+IF(E32="Covered",1,IF(E32="Partial",0.5,0))+IF(E33="Covered",1,IF(E33="Partial",0.5,0))+IF(E35="Covered",1,IF(E35="Partial",0.5,0))+IF(E36="Covered",1,IF(E36="Partial",0.5,0))+IF(E37="Covered",1,IF(E37="Partial",0.5,0))+IF(E39="Covered",1,IF(E39="Partial",0.5,0))+IF(E40="Covered",1,IF(E40="Partial",0.5,0))+IF(E41="Covered",1,IF(E41="Partial",0.5,0)))/11 | F18: =(IF(F29="Covered",1,IF(F29="Partial",0.5,0))+IF(F30="Covered",1,IF(F30="Partial",0.5,0))+IF(F31="Covered",1,IF(F31="Partial",0.5,0))+IF(F32="Covered",1,IF(F32="Partial",0.5,0))+IF(F33="Covered",1,IF(F33="Partial",0.5,0))+IF(F35="Covered",1,IF(F35="Partial",0.5,0))+IF(F36="Covered",1,IF(F36="Partial",0.5,0))+IF(F37="Covered",1,IF(F37="Partial",0.5,0))+IF(F39="Covered",1,IF(F39="Partial",0.5,0))+IF(F40="Covered",1,IF(F40="Partial",0.5,0))+IF(F41="Covered",1,IF(F41="Partial",0.5,0)))/11 | G18: =(IF(G29="Covered",1,IF(G29="Partial",0.5,0))+IF(G30="Covered",1,IF(G30="Partial",0.5,0))+IF(G31="Covered",1,IF(G31="Partial",0.5,0))+IF(G32="Covered",1,IF(G32="Partial",0.5,0))+IF(G33="Covered",1,IF(G33="Partial",0.5,0))+IF(G35="Covered",1,IF(G35="Partial",0.5,0))+IF(G36="Covered",1,IF(G36="Partial",0.5,0))+IF(G37="Covered",1,IF(G37="Partial",0.5,0))+IF(G39="Covered",1,IF(G39="Partial",0.5,0))+IF(G40="Covered",1,IF(G40="Partial",0.5,0))+IF(G41="Covered",1,IF(G41="Partial",0.5,0)))/11 | H18: =(IF(H29="Covered",1,IF(H29="Partial",0.5,0))+IF(H30="Covered",1,IF(H30="Partial",0.5,0))+IF(H31="Covered",1,IF(H31="Partial",0.5,0))+IF(H32="Covered",1,IF(H32="Partial",0.5,0))+IF(H33="Covered",1,IF(H33="Partial",0.5,0))+IF(H35="Covered",1,IF(H35="Partial",0.5,0))+IF(H36="Covered",1,IF(H36="Partial",0.5,0))+IF(H37="Covered",1,IF(H37="Partial",0.5,0))+IF(H39="Covered",1,IF(H39="Partial",0.5,0))+IF(H40="Covered",1,IF(H40="Partial",0.5,0))+IF(H41="Covered",1,IF(H41="Partial",0.5,0)))/11 | I18: =(IF(I29="Covered",1,IF(I29="Partial",0.5,0))+IF(I30="Covered",1,IF(I30="Partial",0.5,0))+IF(I31="Covered",1,IF(I31="Partial",0.5,0))+IF(I32="Covered",1,IF(I32="Partial",0.5,0))+IF(I33="Covered",1,IF(I33="Partial",0.5,0))+IF(I35="Covered",1,IF(I35="Partial",0.5,0))+IF(I36="Covered",1,IF(I36="Partial",0.5,0))+IF(I37="Covered",1,IF(I37="Partial",0.5,0))+IF(I39="Covered",1,IF(I39="Partial",0.5,0))+IF(I40="Covered",1,IF(I40="Partial",0.5,0))+IF(I41="Covered",1,IF(I41="Partial",0.5,0)))/11 | J18: =(IF(J29="Covered",1,IF(J29="Partial",0.5,0))+IF(J30="Covered",1,IF(J30="Partial",0.5,0))+IF(J31="Covered",1,IF(J31="Partial",0.5,0))+IF(J32="Covered",1,IF(J32="Partial",0.5,0))+IF(J33="Covered",1,IF(J33="Partial",0.5,0))+IF(J35="Covered",1,IF(J35="Partial",0.5,0))+IF(J36="Covered",1,IF(J36="Partial",0.5,0))+IF(J37="Covered",1,IF(J37="Partial",0.5,0))+IF(J39="Covered",1,IF(J39="Partial",0.5,0))+IF(J40="Covered",1,IF(J40="Partial",0.5,0))+IF(J41="Covered",1,IF(J41="Partial",0.5,0)))/11 | K18: =(IF(K29="Covered",1,IF(K29="Partial",0.5,0))+IF(K30="Covered",1,IF(K30="Partial",0.5,0))+IF(K31="Covered",1,IF(K31="Partial",0.5,0))+IF(K32="Covered",1,IF(K32="Partial",0.5,0))+IF(K33="Covered",1,IF(K33="Partial",0.5,0))+IF(K35="Covered",1,IF(K35="Partial",0.5,0))+IF(K36="Covered",1,IF(K36="Partial",0.5,0))+IF(K37="Covered",1,IF(K37="Partial",0.5,0))+IF(K39="Covered",1,IF(K39="Partial",0.5,0))+IF(K40="Covered",1,IF(K40="Partial",0.5,0))+IF(K41="Covered",1,IF(K41="Partial",0.5,0)))/11 | ... S18: =(IF(S29="Covered",1,IF(S29="Partial",0.5,0))+IF(S30="Covered",1,IF(S30="Partial",0.5,0))+IF(S31="Covered",1,IF(S31="Partial",0.5,0))+IF(S32="Covered",1,IF(S32="Partial",0.5,0))+IF(S33="Covered",1,IF(S33="Partial",0.5,0))+IF(S35="Covered",1,IF(S35="Partial",0.5,0))+IF(S36="Covered",1,IF(S36="Partial",0.5,0))+IF(S37="Covered",1,IF(S37="Partial",0.5,0))+IF(S39="Covered",1,IF(S39="Partial",0.5,0))+IF(S40="Covered",1,IF(S40="Partial",0.5,0))+IF(S41="Covered",1,IF(S41="Partial",0.5,0)))/11
B19: Scheduling Engine | D19: =(IF(D45="Covered",1,IF(D45="Partial",0.5,0))+IF(D46="Covered",1,IF(D46="Partial",0.5,0))+IF(D47="Covered",1,IF(D47="Partial",0.5,0))+IF(D48="Covered",1,IF(D48="Partial",0.5,0))+IF(D50="Covered",1,IF(D50="Partial",0.5,0))+IF(D51="Covered",1,IF(D51="Partial",0.5,0))+IF(D52="Covered",1,IF(D52="Partial",0.5,0))+IF(D53="Covered",1,IF(D53="Partial",0.5,0))+IF(D54="Covered",1,IF(D54="Partial",0.5,0))+IF(D56="Covered",1,IF(D56="Partial",0.5,0))+IF(D57="Covered",1,IF(D57="Partial",0.5,0))+IF(D58="Covered",1,IF(D58="Partial",0.5,0))+IF(D60="Covered",1,IF(D60="Partial",0.5,0))+IF(D61="Covered",1,IF(D61="Partial",0.5,0)))/14 | E19: =(IF(E45="Covered",1,IF(E45="Partial",0.5,0))+IF(E46="Covered",1,IF(E46="Partial",0.5,0))+IF(E47="Covered",1,IF(E47="Partial",0.5,0))+IF(E48="Covered",1,IF(E48="Partial",0.5,0))+IF(E50="Covered",1,IF(E50="Partial",0.5,0))+IF(E51="Covered",1,IF(E51="Partial",0.5,0))+IF(E52="Covered",1,IF(E52="Partial",0.5,0))+IF(E53="Covered",1,IF(E53="Partial",0.5,0))+IF(E54="Covered",1,IF(E54="Partial",0.5,0))+IF(E56="Covered",1,IF(E56="Partial",0.5,0))+IF(E57="Covered",1,IF(E57="Partial",0.5,0))+IF(E58="Covered",1,IF(E58="Partial",0.5,0))+IF(E60="Covered",1,IF(E60="Partial",0.5,0))+IF(E61="Covered",1,IF(E61="Partial",0.5,0)))/14 | F19: =(IF(F45="Covered",1,IF(F45="Partial",0.5,0))+IF(F46="Covered",1,IF(F46="Partial",0.5,0))+IF(F47="Covered",1,IF(F47="Partial",0.5,0))+IF(F48="Covered",1,IF(F48="Partial",0.5,0))+IF(F50="Covered",1,IF(F50="Partial",0.5,0))+IF(F51="Covered",1,IF(F51="Partial",0.5,0))+IF(F52="Covered",1,IF(F52="Partial",0.5,0))+IF(F53="Covered",1,IF(F53="Partial",0.5,0))+IF(F54="Covered",1,IF(F54="Partial",0.5,0))+IF(F56="Covered",1,IF(F56="Partial",0.5,0))+IF(F57="Covered",1,IF(F57="Partial",0.5,0))+IF(F58="Covered",1,IF(F58="Partial",0.5,0))+IF(F60="Covered",1,IF(F60="Partial",0.5,0))+IF(F61="Covered",1,IF(F61="Partial",0.5,0)))/14 | G19: =(IF(G45="Covered",1,IF(G45="Partial",0.5,0))+IF(G46="Covered",1,IF(G46="Partial",0.5,0))+IF(G47="Covered",1,IF(G47="Partial",0.5,0))+IF(G48="Covered",1,IF(G48="Partial",0.5,0))+IF(G50="Covered",1,IF(G50="Partial",0.5,0))+IF(G51="Covered",1,IF(G51="Partial",0.5,0))+IF(G52="Covered",1,IF(G52="Partial",0.5,0))+IF(G53="Covered",1,IF(G53="Partial",0.5,0))+IF(G54="Covered",1,IF(G54="Partial",0.5,0))+IF(G56="Covered",1,IF(G56="Partial",0.5,0))+IF(G57="Covered",1,IF(G57="Partial",0.5,0))+IF(G58="Covered",1,IF(G58="Partial",0.5,0))+IF(G60="Covered",1,IF(G60="Partial",0.5,0))+IF(G61="Covered",1,IF(G61="Partial",0.5,0)))/14 | H19: =(IF(H45="Covered",1,IF(H45="Partial",0.5,0))+IF(H46="Covered",1,IF(H46="Partial",0.5,0))+IF(H47="Covered",1,IF(H47="Partial",0.5,0))+IF(H48="Covered",1,IF(H48="Partial",0.5,0))+IF(H50="Covered",1,IF(H50="Partial",0.5,0))+IF(H51="Covered",1,IF(H51="Partial",0.5,0))+IF(H52="Covered",1,IF(H52="Partial",0.5,0))+IF(H53="Covered",1,IF(H53="Partial",0.5,0))+IF(H54="Covered",1,IF(H54="Partial",0.5,0))+IF(H56="Covered",1,IF(H56="Partial",0.5,0))+IF(H57="Covered",1,IF(H57="Partial",0.5,0))+IF(H58="Covered",1,IF(H58="Partial",0.5,0))+IF(H60="Covered",1,IF(H60="Partial",0.5,0))+IF(H61="Covered",1,IF(H61="Partial",0.5,0)))/14 | I19: =(IF(I45="Covered",1,IF(I45="Partial",0.5,0))+IF(I46="Covered",1,IF(I46="Partial",0.5,0))+IF(I47="Covered",1,IF(I47="Partial",0.5,0))+IF(I48="Covered",1,IF(I48="Partial",0.5,0))+IF(I50="Covered",1,IF(I50="Partial",0.5,0))+IF(I51="Covered",1,IF(I51="Partial",0.5,0))+IF(I52="Covered",1,IF(I52="Partial",0.5,0))+IF(I53="Covered",1,IF(I53="Partial",0.5,0))+IF(I54="Covered",1,IF(I54="Partial",0.5,0))+IF(I56="Covered",1,IF(I56="Partial",0.5,0))+IF(I57="Covered",1,IF(I57="Partial",0.5,0))+IF(I58="Covered",1,IF(I58="Partial",0.5,0))+IF(I60="Covered",1,IF(I60="Partial",0.5,0))+IF(I61="Covered",1,IF(I61="Partial",0.5,0)))/14 | J19: =(IF(J45="Covered",1,IF(J45="Partial",0.5,0))+IF(J46="Covered",1,IF(J46="Partial",0.5,0))+IF(J47="Covered",1,IF(J47="Partial",0.5,0))+IF(J48="Covered",1,IF(J48="Partial",0.5,0))+IF(J50="Covered",1,IF(J50="Partial",0.5,0))+IF(J51="Covered",1,IF(J51="Partial",0.5,0))+IF(J52="Covered",1,IF(J52="Partial",0.5,0))+IF(J53="Covered",1,IF(J53="Partial",0.5,0))+IF(J54="Covered",1,IF(J54="Partial",0.5,0))+IF(J56="Covered",1,IF(J56="Partial",0.5,0))+IF(J57="Covered",1,IF(J57="Partial",0.5,0))+IF(J58="Covered",1,IF(J58="Partial",0.5,0))+IF(J60="Covered",1,IF(J60="Partial",0.5,0))+IF(J61="Covered",1,IF(J61="Partial",0.5,0)))/14 | K19: =(IF(K45="Covered",1,IF(K45="Partial",0.5,0))+IF(K46="Covered",1,IF(K46="Partial",0.5,0))+IF(K47="Covered",1,IF(K47="Partial",0.5,0))+IF(K48="Covered",1,IF(K48="Partial",0.5,0))+IF(K50="Covered",1,IF(K50="Partial",0.5,0))+IF(K51="Covered",1,IF(K51="Partial",0.5,0))+IF(K52="Covered",1,IF(K52="Partial",0.5,0))+IF(K53="Covered",1,IF(K53="Partial",0.5,0))+IF(K54="Covered",1,IF(K54="Partial",0.5,0))+IF(K56="Covered",1,IF(K56="Partial",0.5,0))+IF(K57="Covered",1,IF(K57="Partial",0.5,0))+IF(K58="Covered",1,IF(K58="Partial",0.5,0))+IF(K60="Covered",1,IF(K60="Partial",0.5,0))+IF(K61="Covered",1,IF(K61="Partial",0.5,0)))/14 | ... S19: =(IF(S45="Covered",1,IF(S45="Partial",0.5,0))+IF(S46="Covered",1,IF(S46="Partial",0.5,0))+IF(S47="Covered",1,IF(S47="Partial",0.5,0))+IF(S48="Covered",1,IF(S48="Partial",0.5,0))+IF(S50="Covered",1,IF(S50="Partial",0.5,0))+IF(S51="Covered",1,IF(S51="Partial",0.5,0))+IF(S52="Covered",1,IF(S52="Partial",0.5,0))+IF(S53="Covered",1,IF(S53="Partial",0.5,0))+IF(S54="Covered",1,IF(S54="Partial",0.5,0))+IF(S56="Covered",1,IF(S56="Partial",0.5,0))+IF(S57="Covered",1,IF(S57="Partial",0.5,0))+IF(S58="Covered",1,IF(S58="Partial",0.5,0))+IF(S60="Covered",1,IF(S60="Partial",0.5,0))+IF(S61="Covered",1,IF(S61="Partial",0.5,0)))/14
B20: Engagement | D20: =(IF(D65="Covered",1,IF(D65="Partial",0.5,0))+IF(D66="Covered",1,IF(D66="Partial",0.5,0))+IF(D68="Covered",1,IF(D68="Partial",0.5,0))+IF(D69="Covered",1,IF(D69="Partial",0.5,0))+IF(D70="Covered",1,IF(D70="Partial",0.5,0))+IF(D71="Covered",1,IF(D71="Partial",0.5,0))+IF(D72="Covered",1,IF(D72="Partial",0.5,0))+IF(D73="Covered",1,IF(D73="Partial",0.5,0))+IF(D75="Covered",1,IF(D75="Partial",0.5,0))+IF(D76="Covered",1,IF(D76="Partial",0.5,0))+IF(D77="Covered",1,IF(D77="Partial",0.5,0))+IF(D78="Covered",1,IF(D78="Partial",0.5,0))+IF(D80="Covered",1,IF(D80="Partial",0.5,0))+IF(D82="Covered",1,IF(D82="Partial",0.5,0))+IF(D83="Covered",1,IF(D83="Partial",0.5,0))+IF(D84="Covered",1,IF(D84="Partial",0.5,0)))/16 | E20: =(IF(E65="Covered",1,IF(E65="Partial",0.5,0))+IF(E66="Covered",1,IF(E66="Partial",0.5,0))+IF(E68="Covered",1,IF(E68="Partial",0.5,0))+IF(E69="Covered",1,IF(E69="Partial",0.5,0))+IF(E70="Covered",1,IF(E70="Partial",0.5,0))+IF(E71="Covered",1,IF(E71="Partial",0.5,0))+IF(E72="Covered",1,IF(E72="Partial",0.5,0))+IF(E73="Covered",1,IF(E73="Partial",0.5,0))+IF(E75="Covered",1,IF(E75="Partial",0.5,0))+IF(E76="Covered",1,IF(E76="Partial",0.5,0))+IF(E77="Covered",1,IF(E77="Partial",0.5,0))+IF(E78="Covered",1,IF(E78="Partial",0.5,0))+IF(E80="Covered",1,IF(E80="Partial",0.5,0))+IF(E82="Covered",1,IF(E82="Partial",0.5,0))+IF(E83="Covered",1,IF(E83="Partial",0.5,0))+IF(E84="Covered",1,IF(E84="Partial",0.5,0)))/16 | F20: =(IF(F65="Covered",1,IF(F65="Partial",0.5,0))+IF(F66="Covered",1,IF(F66="Partial",0.5,0))+IF(F68="Covered",1,IF(F68="Partial",0.5,0))+IF(F69="Covered",1,IF(F69="Partial",0.5,0))+IF(F70="Covered",1,IF(F70="Partial",0.5,0))+IF(F71="Covered",1,IF(F71="Partial",0.5,0))+IF(F72="Covered",1,IF(F72="Partial",0.5,0))+IF(F73="Covered",1,IF(F73="Partial",0.5,0))+IF(F75="Covered",1,IF(F75="Partial",0.5,0))+IF(F76="Covered",1,IF(F76="Partial",0.5,0))+IF(F77="Covered",1,IF(F77="Partial",0.5,0))+IF(F78="Covered",1,IF(F78="Partial",0.5,0))+IF(F80="Covered",1,IF(F80="Partial",0.5,0))+IF(F82="Covered",1,IF(F82="Partial",0.5,0))+IF(F83="Covered",1,IF(F83="Partial",0.5,0))+IF(F84="Covered",1,IF(F84="Partial",0.5,0)))/16 | G20: =(IF(G65="Covered",1,IF(G65="Partial",0.5,0))+IF(G66="Covered",1,IF(G66="Partial",0.5,0))+IF(G68="Covered",1,IF(G68="Partial",0.5,0))+IF(G69="Covered",1,IF(G69="Partial",0.5,0))+IF(G70="Covered",1,IF(G70="Partial",0.5,0))+IF(G71="Covered",1,IF(G71="Partial",0.5,0))+IF(G72="Covered",1,IF(G72="Partial",0.5,0))+IF(G73="Covered",1,IF(G73="Partial",0.5,0))+IF(G75="Covered",1,IF(G75="Partial",0.5,0))+IF(G76="Covered",1,IF(G76="Partial",0.5,0))+IF(G77="Covered",1,IF(G77="Partial",0.5,0))+IF(G78="Covered",1,IF(G78="Partial",0.5,0))+IF(G80="Covered",1,IF(G80="Partial",0.5,0))+IF(G82="Covered",1,IF(G82="Partial",0.5,0))+IF(G83="Covered",1,IF(G83="Partial",0.5,0))+IF(G84="Covered",1,IF(G84="Partial",0.5,0)))/16 | H20: =(IF(H65="Covered",1,IF(H65="Partial",0.5,0))+IF(H66="Covered",1,IF(H66="Partial",0.5,0))+IF(H68="Covered",1,IF(H68="Partial",0.5,0))+IF(H69="Covered",1,IF(H69="Partial",0.5,0))+IF(H70="Covered",1,IF(H70="Partial",0.5,0))+IF(H71="Covered",1,IF(H71="Partial",0.5,0))+IF(H72="Covered",1,IF(H72="Partial",0.5,0))+IF(H73="Covered",1,IF(H73="Partial",0.5,0))+IF(H75="Covered",1,IF(H75="Partial",0.5,0))+IF(H76="Covered",1,IF(H76="Partial",0.5,0))+IF(H77="Covered",1,IF(H77="Partial",0.5,0))+IF(H78="Covered",1,IF(H78="Partial",0.5,0))+IF(H80="Covered",1,IF(H80="Partial",0.5,0))+IF(H82="Covered",1,IF(H82="Partial",0.5,0))+IF(H83="Covered",1,IF(H83="Partial",0.5,0))+IF(H84="Covered",1,IF(H84="Partial",0.5,0)))/16 | I20: =(IF(I65="Covered",1,IF(I65="Partial",0.5,0))+IF(I66="Covered",1,IF(I66="Partial",0.5,0))+IF(I68="Covered",1,IF(I68="Partial",0.5,0))+IF(I69="Covered",1,IF(I69="Partial",0.5,0))+IF(I70="Covered",1,IF(I70="Partial",0.5,0))+IF(I71="Covered",1,IF(I71="Partial",0.5,0))+IF(I72="Covered",1,IF(I72="Partial",0.5,0))+IF(I73="Covered",1,IF(I73="Partial",0.5,0))+IF(I75="Covered",1,IF(I75="Partial",0.5,0))+IF(I76="Covered",1,IF(I76="Partial",0.5,0))+IF(I77="Covered",1,IF(I77="Partial",0.5,0))+IF(I78="Covered",1,IF(I78="Partial",0.5,0))+IF(I80="Covered",1,IF(I80="Partial",0.5,0))+IF(I82="Covered",1,IF(I82="Partial",0.5,0))+IF(I83="Covered",1,IF(I83="Partial",0.5,0))+IF(I84="Covered",1,IF(I84="Partial",0.5,0)))/16 | J20: =(IF(J65="Covered",1,IF(J65="Partial",0.5,0))+IF(J66="Covered",1,IF(J66="Partial",0.5,0))+IF(J68="Covered",1,IF(J68="Partial",0.5,0))+IF(J69="Covered",1,IF(J69="Partial",0.5,0))+IF(J70="Covered",1,IF(J70="Partial",0.5,0))+IF(J71="Covered",1,IF(J71="Partial",0.5,0))+IF(J72="Covered",1,IF(J72="Partial",0.5,0))+IF(J73="Covered",1,IF(J73="Partial",0.5,0))+IF(J75="Covered",1,IF(J75="Partial",0.5,0))+IF(J76="Covered",1,IF(J76="Partial",0.5,0))+IF(J77="Covered",1,IF(J77="Partial",0.5,0))+IF(J78="Covered",1,IF(J78="Partial",0.5,0))+IF(J80="Covered",1,IF(J80="Partial",0.5,0))+IF(J82="Covered",1,IF(J82="Partial",0.5,0))+IF(J83="Covered",1,IF(J83="Partial",0.5,0))+IF(J84="Covered",1,IF(J84="Partial",0.5,0)))/16 | K20: =(IF(K65="Covered",1,IF(K65="Partial",0.5,0))+IF(K66="Covered",1,IF(K66="Partial",0.5,0))+IF(K68="Covered",1,IF(K68="Partial",0.5,0))+IF(K69="Covered",1,IF(K69="Partial",0.5,0))+IF(K70="Covered",1,IF(K70="Partial",0.5,0))+IF(K71="Covered",1,IF(K71="Partial",0.5,0))+IF(K72="Covered",1,IF(K72="Partial",0.5,0))+IF(K73="Covered",1,IF(K73="Partial",0.5,0))+IF(K75="Covered",1,IF(K75="Partial",0.5,0))+IF(K76="Covered",1,IF(K76="Partial",0.5,0))+IF(K77="Covered",1,IF(K77="Partial",0.5,0))+IF(K78="Covered",1,IF(K78="Partial",0.5,0))+IF(K80="Covered",1,IF(K80="Partial",0.5,0))+IF(K82="Covered",1,IF(K82="Partial",0.5,0))+IF(K83="Covered",1,IF(K83="Partial",0.5,0))+IF(K84="Covered",1,IF(K84="Partial",0.5,0)))/16 | ... S20: =(IF(S65="Covered",1,IF(S65="Partial",0.5,0))+IF(S66="Covered",1,IF(S66="Partial",0.5,0))+IF(S68="Covered",1,IF(S68="Partial",0.5,0))+IF(S69="Covered",1,IF(S69="Partial",0.5,0))+IF(S70="Covered",1,IF(S70="Partial",0.5,0))+IF(S71="Covered",1,IF(S71="Partial",0.5,0))+IF(S72="Covered",1,IF(S72="Partial",0.5,0))+IF(S73="Covered",1,IF(S73="Partial",0.5,0))+IF(S75="Covered",1,IF(S75="Partial",0.5,0))+IF(S76="Covered",1,IF(S76="Partial",0.5,0))+IF(S77="Covered",1,IF(S77="Partial",0.5,0))+IF(S78="Covered",1,IF(S78="Partial",0.5,0))+IF(S80="Covered",1,IF(S80="Partial",0.5,0))+IF(S82="Covered",1,IF(S82="Partial",0.5,0))+IF(S83="Covered",1,IF(S83="Partial",0.5,0))+IF(S84="Covered",1,IF(S84="Partial",0.5,0)))/16
B22: 1 · HCHB INTEGRATION — 25 points · pick one rung from A1
B23: Rung | C23: A1
B24: Sync latency addressed? | C24: caps at 20 if No | D24: Yes | E24: Yes | F24: Yes | G24: Yes | H24: Yes | I24: Yes | J24: Yes | K24: Yes | L24: Yes | M24: Yes | N24: Yes | O24: Yes | P24: Yes | Q24: Yes | R24: Yes | S24: Yes
B26: 2 · SCOPE FOOTPRINT — 30 points · Covered 1.0 · Partial 0.5 · — 0
B27: CAPACITY MANAGEMENT · 11 elements · 10 points
B28: Workforce supply | C28: B1
B29: Roster by discipline, role (assessing vs. assistant), FTE and employment type | C29: CAP-01
B30: Start-of-care capable clinicians, measured as their own distinct capacity | C30: CAP-02
B31: Specialty competencies, plus orientation and ramp status | C31: CAP-03
B32: Per-diem and float pool | C32: CAP-04
B33: On-call and weekend rotation load | C33: CAP-05
B34: Availability & reach | C34: B2
B35: Approved time off and working availability | C35: CAP-06
B36: Clinician territory assignment by zip, against branch coverage area | C36: CAP-07
B37: Reachability from the clinician's home base, measured by drive time | C37: CAP-08
B38: The capacity math | C38: B3
B39: Visit weighting — the point value per visit type, and the productivity target and ceiling it is measured against | C39: CAP-09
... B41: Referral inflow and discharge outflow against the envelope | C41: CAP-11
B43: SCHEDULING ENGINE · 14 elements · 10 points
B44: Demand | C44: B4
B45: Plan-of-care orders, ordered frequency and visit types, from the EMR (Home Care Home Base) and the intake platform | C45: SCH-01
B46: Authorization status and payer rules attached to each visit | C46: SCH-02
B47: Order, consent and readiness state — what is schedulable, not merely ordered | C47: SCH-03
B48: The compliance window each visit has to fall inside | C48: SCH-04
...

Sheet Guide
B2: How to score
B3: Every part is a percentage times a budget. Part 1 is the one exception — a checkbox ladder, so the leadership priority cannot drift.
B5: THE FIVE PARTS
B6: Part | C6: Points | D6: Answered from
B7: 1 · HCHB Integration | C7: 25 | D7: A1 — tick one rung. Ambiguous → take the lower rung and raise a flag. An answer silent on sync latency caps at 20.
B8: 2 · Scope Footprint | C8: 30 | D8: Section B is the claim, Section C is the evidence. 41 elements, 10 points per arena. Cite or it is a Partial.
B9: 3 · Sophistication | C9: 20 | D9: C1–C7 plus A2/A3. Five dimensions on the evidence ladder.
B10: 4 · Clinician & Adoption | C10: 10 | D10: Section D. Adoption, more than algorithm quality, decides this.
B11: 5 · Partnership | C11: 15 | D11: Section E. An offer with structure is a 3–4; 'open to discussing' is a 1.
B12: TOTAL | C12: 100
B14: PART 1 — THE HCHB LADDER
B15: Live, bi-directional, multi-customer | C15: 25 | D15: In production with more than one customer, reads and writes, published API / HL7 / FHIR, with a go-live date.
B16: Live, single customer or one-way | C16: 20 | D16: In production, but one customer only, or it reads without writing back.
B17: Live via a partner or a brittle method | C17: 12 | D17: Third party, flat file, direct database, or screen automation.
B18: In development, dated | C18: 6 | D18: Building, with a committed date in the answer.
B19: Roadmap, undated | C19: 2 | D19: Named as intent. No date, no commitment.
B20: None, and no path | C20: 0 | D20: No integration and no credible route to one.
B22: PART 2 — THE FOOTPRINT MARKS
B23: Covered | C23: 1.0 | D23: The product does this today — stated plainly, or evidenced in a Section C walkthrough.
B24: Partial | C24: 0.5 | D24: Adjacent, configurable-with-work, delivered by a partner, roadmapped with a date, or claimed without any supporting detail.
B25: — | C25: 0 | D25: Absent, explicitly out of scope, or done by a person in their model.
B27: PARTS 3–5 — THE EVIDENCE LADDER
B28: 0 — Not addressed | D28: Skipped, or answered without answering.
B29: 1 — Asserted | D29: They say they do it. Nothing behind it.
B30: 2 — Described | D30: We can picture the feature.
B31: 3 — Mechanism | D31: We can picture how it decides — the inputs, the logic, the configuration.
B32: 4 — Proven | D32: Mechanism plus evidence: numbers, a named customer, a period, a baseline.
B34: BANDS
B35: Advance | C35: 80–100 | D35: Demo, references, deeper diligence.
B36: Consider | C36: 65–79 | D36: Advance only if a differentiator or a low-cost gap-closer justifies it.
B37: Hold | C37: 50–64 | D37: Park unless the field thins.
B38: Decline | C38: < 50 | D38: Close out with thanks.
B39: Conditional | C39: HCHB < 12 | D39: Any band, but advancing means explicitly accepting an integration to be built, on their timeline, at our risk. Ties break on HCHB, then Scheduling.

Sheet Lists
B1: HCHB rung | C1: Points | E1: Ladder
B2: Live, bi-directional, multi-customer | C2: 25 | E2: 0 — Not addressed
B3: Live, single customer or one-way | C3: 20 | E3: 1 — Asserted
B4: Live via a partner or a brittle method | C4: 12 | E4: 2 — Described
B5: In development, dated | C5: 6 | E5: 3 — Mechanism
B6: Roadmap, undated | C6: 2 | E6: 4 — Proven
B7: None, and no path | C7: 0
