Workbook

Sheet Start Here
B2: COMPASSUS · HOME HEALTH
B3: Vendor Scorecard — Fast
B4: The questionnaire is the rubric. Read the return top to bottom and fill the sheet top to bottom. Seven marks a vendor, about two minutes.
B7: HOW IT WORKS
B8: Every one of the 17 questions on the questionnaire has a row on the Scorecard tab, in the order it appears on the form. Seven rows take a mark. The rest raise a flag or a note — and they say so, so nothing looks forgotten. What isn't scored becomes what we go and ask at the demo.
B9: Scored on the same 100 points and the same bands as the full scorecard, so the two are directly comparable. This one is coarser, not different: it gives one mark where the full sheet gives several, so the two can disagree on a close call. That is the trade for speed.
B11: THE SEVEN MARKS
B12: Question | C12: Mark | D12: Points
B13: A1 | C13: Home Care Home Base integration | D13: 25
B14: Section B | C14: Capacity — how much of it they cover | D14: 10
B15: Section B | C15: Scheduling — how much of it they cover | D15: 10
B16: Section B | C16: Engagement — how much of it they cover | D16: 10
B17: C1–C5, C7 | C17: Sophistication — how much of the work the product does | D17: 20
B18: D1–D3 | C18: Clinician fit | D18: 10
B19: E1–E4 | C19: Partnership | D19: 15
C20: TOTAL | D20: 100
B22: A1 · HOME CARE HOME BASE — pick one line
B23: 25 | C23: Live — reads and writes, several customers
B24: 20 | C24: Live — one customer, or one-way only
B25: 12 | C25: Live — via a partner, flat file or screen scraping
B26: 6 | C26: In development — with a date
B27: 2 | C27: Roadmap — no date
B28: 0 | C28: None, and no path to one
B30: SECTION B · SCOPE — one mark per arena, 0 to 3
B31: Read the eleven areas each vendor rated themselves on, then give one mark per arena. Capacity has 3 areas, Scheduling 4, Engagement 4 — so counting their yeses gets you most of the way there. Where Section C contradicts Section B, believe Section C.
B32: 3 | C32: Covers essentially all of it
B33: 2 | C33: Covers most of it
B34: 1 | C34: Covers some of it
B35: 0 | C35: Little or none
B37: SECTION C · SOPHISTICATION — one mark, 0 to 4
B38: How much of the work the product does. This is the Read / Assist / Control language already in our workbook. Score what the product does, not how much the vendor wrote about it — a short answer describing an optimiser still scores 4. How it does it is a demo question, not a reason to mark it down.
B39: 4 | C39: Runs it — decides across the whole picture, and re-decides when things change
B40: 3 | C40: Recommends it — works out the answer and proposes it; a person confirms
B41: 2 | C41: Checks it — applies rules and flags problems; a person still works it
B42: 1 | C42: Shows it — surfaces the information; a person does all the work
B43: 0 | C43: Not addressed
B44: A 4 is not automatically what we want. Where we said Assist, a product that decides on its own is a risk worth a note.
B46: SECTION D · CLINICIAN FIT — one mark, 0 to 4
B47: 4 | C47: Clinician keeps real control, and they showed adoption data
B48: 3 | C48: Clinician keeps real control; adoption claimed but not shown
...

Sheet Scorecard
B2: COMPASSUS · HOME HEALTH
B3: Vendor Scorecard — Fast
B4: The rows are the questionnaire, in order. Seven take a mark; three raise a flag; the rest are notes. Grey cells are formulas.
B6: VENDOR | E6: Vendor 01 | F6: Vendor 02 | G6: Vendor 03 | H6: Vendor 04 | I6: Vendor 05 | J6: Vendor 06 | K6: Vendor 07 | L6: Vendor 08 | M6: Vendor 09 | N6: Vendor 10 | O6: Vendor 11 | P6: Vendor 12 | Q6: Vendor 13 | R6: Vendor 14 | S6: Vendor 15 | T6: Vendor 16
B8: SCORE
B9: TOTAL | C9: of 100 | E9: =IFERROR(VLOOKUP(E14,Lists!$B$2:$C$7,2,FALSE),0)+IFERROR(VALUE(LEFT(E19,1)),0)/3*10+IFERROR(VALUE(LEFT(E20,1)),0)/3*10+IFERROR(VALUE(LEFT(E21,1)),0)/3*10+IFERROR(VALUE(LEFT(E24,1)),0)/4*20+IFERROR(VALUE(LEFT(E28,1)),0)/4*10+IFERROR(VALUE(LEFT(E31,1)),0)/4*15 | F9: =IFERROR(VLOOKUP(F14,Lists!$B$2:$C$7,2,FALSE),0)+IFERROR(VALUE(LEFT(F19,1)),0)/3*10+IFERROR(VALUE(LEFT(F20,1)),0)/3*10+IFERROR(VALUE(LEFT(F21,1)),0)/3*10+IFERROR(VALUE(LEFT(F24,1)),0)/4*20+IFERROR(VALUE(LEFT(F28,1)),0)/4*10+IFERROR(VALUE(LEFT(F31,1)),0)/4*15 | G9: =IFERROR(VLOOKUP(G14,Lists!$B$2:$C$7,2,FALSE),0)+IFERROR(VALUE(LEFT(G19,1)),0)/3*10+IFERROR(VALUE(LEFT(G20,1)),0)/3*10+IFERROR(VALUE(LEFT(G21,1)),0)/3*10+IFERROR(VALUE(LEFT(G24,1)),0)/4*20+IFERROR(VALUE(LEFT(G28,1)),0)/4*10+IFERROR(VALUE(LEFT(G31,1)),0)/4*15 | H9: =IFERROR(VLOOKUP(H14,Lists!$B$2:$C$7,2,FALSE),0)+IFERROR(VALUE(LEFT(H19,1)),0)/3*10+IFERROR(VALUE(LEFT(H20,1)),0)/3*10+IFERROR(VALUE(LEFT(H21,1)),0)/3*10+IFERROR(VALUE(LEFT(H24,1)),0)/4*20+IFERROR(VALUE(LEFT(H28,1)),0)/4*10+IFERROR(VALUE(LEFT(H31,1)),0)/4*15 | I9: =IFERROR(VLOOKUP(I14,Lists!$B$2:$C$7,2,FALSE),0)+IFERROR(VALUE(LEFT(I19,1)),0)/3*10+IFERROR(VALUE(LEFT(I20,1)),0)/3*10+IFERROR(VALUE(LEFT(I21,1)),0)/3*10+IFERROR(VALUE(LEFT(I24,1)),0)/4*20+IFERROR(VALUE(LEFT(I28,1)),0)/4*10+IFERROR(VALUE(LEFT(I31,1)),0)/4*15 | J9: =IFERROR(VLOOKUP(J14,Lists!$B$2:$C$7,2,FALSE),0)+IFERROR(VALUE(LEFT(J19,1)),0)/3*10+IFERROR(VALUE(LEFT(J20,1)),0)/3*10+IFERROR(VALUE(LEFT(J21,1)),0)/3*10+IFERROR(VALUE(LEFT(J24,1)),0)/4*20+IFERROR(VALUE(LEFT(J28,1)),0)/4*10+IFERROR(VALUE(LEFT(J31,1)),0)/4*15 | K9: =IFERROR(VLOOKUP(K14,Lists!$B$2:$C$7,2,FALSE),0)+IFERROR(VALUE(LEFT(K19,1)),0)/3*10+IFERROR(VALUE(LEFT(K20,1)),0)/3*10+IFERROR(VALUE(LEFT(K21,1)),0)/3*10+IFERROR(VALUE(LEFT(K24,1)),0)/4*20+IFERROR(VALUE(LEFT(K28,1)),0)/4*10+IFERROR(VALUE(LEFT(K31,1)),0)/4*15 | L9: =IFERROR(VLOOKUP(L14,Lists!$B$2:$C$7,2,FALSE),0)+IFERROR(VALUE(LEFT(L19,1)),0)/3*10+IFERROR(VALUE(LEFT(L20,1)),0)/3*10+IFERROR(VALUE(LEFT(L21,1)),0)/3*10+IFERROR(VALUE(LEFT(L24,1)),0)/4*20+IFERROR(VALUE(LEFT(L28,1)),0)/4*10+IFERROR(VALUE(LEFT(L31,1)),0)/4*15 | ... T9: =IFERROR(VLOOKUP(T14,Lists!$B$2:$C$7,2,FALSE),0)+IFERROR(VALUE(LEFT(T19,1)),0)/3*10+IFERROR(VALUE(LEFT(T20,1)),0)/3*10+IFERROR(VALUE(LEFT(T21,1)),0)/3*10+IFERROR(VALUE(LEFT(T24,1)),0)/4*20+IFERROR(VALUE(LEFT(T28,1)),0)/4*10+IFERROR(VALUE(LEFT(T31,1)),0)/4*15
B10: Band | C10: 80 Advance · 65 Consider · 50 Hold | E10: =IF(IFERROR(VLOOKUP(E14,Lists!$B$2:$C$7,2,FALSE),0)<12,"Conditional — ","")&IF(E9>=80,"Advance",IF(E9>=65,"Consider",IF(E9>=50,"Hold","Decline"))) | F10: =IF(IFERROR(VLOOKUP(F14,Lists!$B$2:$C$7,2,FALSE),0)<12,"Conditional — ","")&IF(F9>=80,"Advance",IF(F9>=65,"Consider",IF(F9>=50,"Hold","Decline"))) | G10: =IF(IFERROR(VLOOKUP(G14,Lists!$B$2:$C$7,2,FALSE),0)<12,"Conditional — ","")&IF(G9>=80,"Advance",IF(G9>=65,"Consider",IF(G9>=50,"Hold","Decline"))) | H10: =IF(IFERROR(VLOOKUP(H14,Lists!$B$2:$C$7,2,FALSE),0)<12,"Conditional — ","")&IF(H9>=80,"Advance",IF(H9>=65,"Consider",IF(H9>=50,"Hold","Decline"))) | I10: =IF(IFERROR(VLOOKUP(I14,Lists!$B$2:$C$7,2,FALSE),0)<12,"Conditional — ","")&IF(I9>=80,"Advance",IF(I9>=65,"Consider",IF(I9>=50,"Hold","Decline"))) | J10: =IF(IFERROR(VLOOKUP(J14,Lists!$B$2:$C$7,2,FALSE),0)<12,"Conditional — ","")&IF(J9>=80,"Advance",IF(J9>=65,"Consider",IF(J9>=50,"Hold","Decline"))) | K10: =IF(IFERROR(VLOOKUP(K14,Lists!$B$2:$C$7,2,FALSE),0)<12,"Conditional — ","")&IF(K9>=80,"Advance",IF(K9>=65,"Consider",IF(K9>=50,"Hold","Decline"))) | L10: =IF(IFERROR(VLOOKUP(L14,Lists!$B$2:$C$7,2,FALSE),0)<12,"Conditional — ","")&IF(L9>=80,"Advance",IF(L9>=65,"Consider",IF(L9>=50,"Hold","Decline"))) | ... T10: =IF(IFERROR(VLOOKUP(T14,Lists!$B$2:$C$7,2,FALSE),0)<12,"Conditional — ","")&IF(T9>=80,"Advance",IF(T9>=65,"Consider",IF(T9>=50,"Hold","Decline")))
B11: Flags | C11: stop-checks raised, of three | E11: =(IF(E15="STOP-CHECK",1,0)+IF(E16="STOP-CHECK",1,0)+IF(E25="STOP-CHECK",1,0)) | F11: =(IF(F15="STOP-CHECK",1,0)+IF(F16="STOP-CHECK",1,0)+IF(F25="STOP-CHECK",1,0)) | G11: =(IF(G15="STOP-CHECK",1,0)+IF(G16="STOP-CHECK",1,0)+IF(G25="STOP-CHECK",1,0)) | H11: =(IF(H15="STOP-CHECK",1,0)+IF(H16="STOP-CHECK",1,0)+IF(H25="STOP-CHECK",1,0)) | I11: =(IF(I15="STOP-CHECK",1,0)+IF(I16="STOP-CHECK",1,0)+IF(I25="STOP-CHECK",1,0)) | J11: =(IF(J15="STOP-CHECK",1,0)+IF(J16="STOP-CHECK",1,0)+IF(J25="STOP-CHECK",1,0)) | K11: =(IF(K15="STOP-CHECK",1,0)+IF(K16="STOP-CHECK",1,0)+IF(K25="STOP-CHECK",1,0)) | L11: =(IF(L15="STOP-CHECK",1,0)+IF(L16="STOP-CHECK",1,0)+IF(L25="STOP-CHECK",1,0)) | ... T11: =(IF(T15="STOP-CHECK",1,0)+IF(T16="STOP-CHECK",1,0)+IF(T25="STOP-CHECK",1,0))
B13: A · COMPANY AND PRODUCT
B14: A1 | C14: Home Care Home Base integration | D14: Pick one line · 25 points
B15: A2 | C15: Customers, scale and references | D15: Flag · stop-check if one customer or no references
B16: A3 | C16: Measured impact | D16: Flag · watch if no baseline or period
B18: B · COVERAGE SELF-ASSESSMENT — how much of our scope they cover
B19: Section B | C19: Capacity | D19: Workforce supply · availability & reach · the capacity math · 0–3 · 10 points
B20: Section B | C20: Scheduling | D20: Demand · matching · routing & the week · exceptions · 0–3 · 10 points
B21: Section B | C21: Engagement | D21: Before the visit · when plans change · incentives · care team · 0–3 · 10 points
B23: C · HOW YOUR PRODUCT WORKS
B24: C1–C5, C7 | C24: Sophistication | D24: How much of the work it does · 0–4 · 20 points
B25: C6 | C25: When your product is down | D25: Flag · stop-check if no uptime figure or commitment
B27: D · THE CLINICIAN'S PLACE IN THE MODEL
B28: D1–D3 | C28: Clinician fit | D28: Control, and whether adoption is shown · 0–4 · 10 points
B30: E · FIT AND PARTNERSHIP
B31: E1–E4 | C31: Partnership | D31: Terms offered, and the change-management story · 0–4 · 15 points
B33: NOTES — one line each. This is what we go and ask.
C34: What stands out | D34: against the field, or against our own thinking
C35: What worries me | D35: including anything flagged above
C36: What to go and ask | D36: the demo agenda

Sheet Lists
B1: A1 rung | C1: Points | E1: Scope | G1: Sophistication | I1: Clinician | K1: Partnership
B2: Live — reads and writes, several customers | C2: 25 | E2: 0 — Little or none | G2: 0 — Not addressed | I2: 0 — Didn't answer | K2: 0 — Didn't answer
B3: Live — one customer, or one-way only | C3: 20 | E3: 1 — Covers some of it | G3: 1 — Shows it | I3: 1 — System decides, clinician cannot override | K3: 1 — Standard commercial relationship only
B4: Live — via a partner, flat file or screen scraping | C4: 12 | E4: 2 — Covers most of it | G4: 2 — Checks it | I4: 2 — System decides, clinician can override | K4: 2 — Willing, but no structure offered
B5: In development — with a date | C5: 6 | E5: 3 — Covers essentially all of it | G5: 3 — Recommends it | I5: 3 — Clinician keeps real control; adoption claimed | K5: 3 — Specific terms, or a real change-management story
B6: Roadmap — no date | C6: 2 | G6: 4 — Runs it | I6: 4 — Clinician keeps real control; adoption shown with data | K6: 4 — Specific terms and a real change-management story
B7: None, and no path to one | C7: 0
