Workbook

Sheet Summary
A1: What this program is worth, and when
A2: This page is the answer. Everything on it is calculated from the Inputs page. To test a different assumption, change it there and this updates by itself.
A3: =CONCATENATE("Currently showing: ",Inputs!B75," value assumptions against ",Inputs!B77," program cost") -> Currently showing: value assumptions against program cost
B5: Year 1 | C5: Year 2 | D5: Year 3 | E5: Three years | F5: What this row is telling you
A6: Full annual value, once every branch is live | B6: =INDEX(Value!$B$12:$D$12,Inputs!$B$56) -> 15254000 | C6: =INDEX(Value!$B$12:$D$12,Inputs!$B$56) -> 15254000 | D6: =INDEX(Value!$B$12:$D$12,Inputs!$B$56) -> 15254000 | F6: The yearly benefit after the program has finished rolling out to all branches. It is the same in each column because it is the finished-state number, not what we actually collect that year.
A7: How much of it we actually collect that year | B7: =Inputs!B51 -> 0.2 | C7: =Inputs!C51 -> 0.6 | D7: =Inputs!D51 -> 1 | F7: Rollout takes time. A branch that has not gone live yet delivers nothing. This is the share of the finished-state number we expect to see in each year.
A8: Discount for programs falling short | B8: =Inputs!$B$52 -> 0 | C8: =Inputs!$B$52 -> 0 | D8: =Inputs!$B$52 -> 0 | F8: Large technology programs typically deliver less than promised. Set this above zero on the Inputs page to see a deliberately cautious version of the same case.
A9: Value we expect to collect | B9: =B6*B7*(1-B8) -> 3050800 | C9: =C6*C7*(1-C8) -> 9152400 | D9: =D6*D7*(1-D8) -> 15254000 | E9: =SUM(B9:D9) -> 27457200 | F9: The first row, reduced by the rollout share and by the shortfall discount. This is the honest expectation, not the promise.
A10: What the program costs us | B10: =Cost!B13 -> 10900000 | C10: =Cost!C13 -> 6100000 | D10: =Cost!D13 -> 5200000 | E10: =Cost!E13 -> 22200000 | F10: Everything: software, putting it in, connecting it to our systems, our own people's time, training, and support. Software is the small part.
A11: Net, value minus cost | B11: =B9-B10 -> -7849200 | C11: =C9-C10 -> 3052400 | D11: =D9-D10 -> 10054000 | E11: =E9-E10 -> 5257200 | F11: Negative means we are still paying it back. Positive means it has started returning more than it takes.
A12: Running total | B12: =B11 -> -7849200 | C12: =B12+C11 -> -4796800 | D12: =C12+D11 -> 5257200 | F12: The year the running total turns positive is the year the program has paid for itself.
A14: When it pays for itself | B14: =IF(D12>0,IF(C12>0,IF(B12>0,"Year 1","Year 2"),"Year 3"),"Later than year 3") -> Year 3 | F14: The year the running total crosses from negative to positive.
A15: Return over three years | B15: =IF(E10=0,0,E11/E10) -> 0.23681081 | F15: Net gain divided by what we spent. 25 percent means we got back a quarter more than we put in, over three years.
A17: Where the money comes from, on the version currently shown
A18: =Value!A5 -> More patients started on service | B18: =INDEX(Value!$B$5:$D$5,Inputs!$B$56) -> 2304000 | F18: =Value!E5 -> We take on more patients without hiring, because we can see who has room and answer the hospital faster.
A19: =Value!A6 -> Fewer approved visits going unstaffed | B19: =INDEX(Value!$B$6:$D$6,Inputs!$B$56) -> 2470000 | F19: =Value!E6 -> When a visit falls through, someone else picks it up quickly instead of it being lost.
A20: =Value!A7 -> Fewer Medicare periods falling short on visits | B20: =INDEX(Value!$B$7:$D$7,Inputs!$B$56) -> 1120000 | F20: =Value!E7 -> We spot a 30-day period heading for too few visits while there is still time to put a clinically needed visit back.
A21: =Value!A8 -> Fewer scheduling roles needed | B21: =INDEX(Value!$B$8:$D$8,Inputs!$B$56) -> 3600000 | F21: =Value!E8 -> Assigning visits takes far fewer people once the repetitive parts happen by themselves.
A22: =Value!A9 -> Less premium labor | B22: =INDEX(Value!$B$9:$D$9,Inputs!$B$56) -> 2880000 | F22: =Value!E9 -> Fewer visits covered by agency staff, overtime, or bonus pay because we could not find anyone else in time.
A23: =Value!A10 -> Fewer clinicians leaving | B23: =INDEX(Value!$B$10:$D$10,Inputs!$B$56) -> 1600000 | F23: =Value!E10 -> A steadier, more predictable week means fewer clinicians resign, and we spend less replacing them.
A24: =Value!A11 -> Less driving | B24: =INDEX(Value!$B$11:$D$11,Inputs!$B$56) -> 1280000 | F24: =Value!E11 -> Clinicians drive fewer miles because their day is grouped sensibly and territories follow real drive times.
A25: Total | B25: =SUM(B18:B24) -> 15254000
A27: Three things to know before quoting any of this
A28: - Three figures on the Inputs page are highlighted yellow because we do not have the real number yet. The largest lever moves directly with the first of them.
A29: - This shows the whole benefit. If someone asks what we get that we could not get by simply configuring what we already own, that is a smaller number and a fair question.
A30: - Type 56% into the shortfall discount on the Inputs page to see how this looks if the program delivers what large technology programs typically deliver.

Sheet Inputs
A1: Every number this model uses, and where each one came from
A2: Blue numbers are yours to change. Black numbers work themselves out. A yellow number means we do not have the real figure yet and this one is a placeholder.
A4: HOW BIG WE ARE
A5: Line item | B5: Value | C5: Unit | D5: What this is, in plain terms | E5: Why it is here, and what it changes | F5: Where the number came from | G5: How sure we are
A6: Branches | B6: 80 | C6: count | D6: The number of home health locations in the company. | E6: Almost every figure below is per-branch and multiplied up by this. If the branch count is wrong, the whole model is wrong by the same proportion. | F6: The 8.13 workbook | G6: Good
A7: Field clinicians | B7: 3000 | C7: count | D7: Nurses, therapists, and aides who see patients in the home. | E7: Sets the size of the workforce levers, especially turnover and travel. | F7: On-site session, 13 August | G7: Good
A8: Share of clinicians paid per visit | B8: 0.7 | C8: % | D8: The portion paid for each visit they complete, rather than a salary or an hourly wage. | E8: This is the single most important number in the model. When a clinician is paid per visit, we pay the same whether their day is efficient or not, so time saved does not become money saved. It becomes capacity, and capacity only becomes money if we fill it. | F8: Colin, 26 August | G8: Given
A9: Schedulers today | B9: 300 | C9: count | D9: People whose job is assigning visits to clinicians. | E9: The starting point for the administrative savings lever. | F9: On-site session, 13 August | G9: Stated, not counted
A10: Home health revenue | B10: 549000000 | C10: $ | D10: Total money the home health business brings in each year. | E10: The base every percentage claim is measured against. | F10: The coding business case | G10: Good
A11: Medicare fee-for-service revenue | B11: 260000000 | C11: $ | D11: The part of revenue that comes from traditional Medicare, where we are paid a fixed amount for a 30-day period rather than for each visit. | E11: Splits the book in two, because the two halves respond in opposite ways. On this half, an extra visit costs money and earns nothing. | F11: The coding business case | G11: Good
A12: All other payer revenue | B12: =B10-B11 -> 289000000 | C12: $ | D12: Everything that is not traditional Medicare: Medicare Advantage, commercial insurance, and Medicaid. | E12: On this half we are paid for each visit delivered, so an extra visit does earn money. That is why the two halves are modeled separately. | F12: Calculated: total minus Medicare
A13: Admissions per year, all branches | B13: 48000 | C13: count | D13: Every new patient started on service across the company in a year. Not a referral, and not a visit. | E13: The growth lever is a percentage of this number, so it moves up and down with it directly. We have flagged it because the current figure does not fit our revenue: 48,000 admissions into $549 million implies about $11,400 of revenue per patient, and a home health episode is nearer $2,000 to $4,000. | F13: 600 per branch, times 80 branches, from the 8.13 workbook | G13: Needs checking
A14: Medicare 30-day payment periods per year | B14: 80000 | C14: count | D14: Traditional Medicare pays in 30-day blocks. A patient on service for two months creates two of them. | E14: The visit-shortfall lever is a percentage of this number. A second reasonable calculation gives 128,000 instead of 80,000, and the two cannot both be right. | F14: 1,000 per branch, times 80 branches, from the 8.13 workbook | G14: Needs checking
A15: Total visits per year | B15: 3000000 | C15: count | D15: Every home visit made by every clinician in a year. | E15: Background scale for the travel and throughput levers. | F15: Estimated: 3,000 clinicians at roughly 1,000 visits each | G15: Estimate
A16: Visits per year on non-Medicare payers | B16: 1900000 | C16: count | D16: The share of those visits covered by insurers who pay per visit. | E16: The staffing-gap lever only earns money on these visits, so this is its base. | F16: Estimated from the non-Medicare share of revenue | G16: Estimate
A18: WHAT ONE OF EACH THING IS WORTH
A19: Line item | B19: Value | C19: Unit | D19: What this is, in plain terms | E19: Why it is here, and what it changes | F19: Where the number came from | G19: How sure we are
A20: Margin per additional admission | B20: 1200 | C20: $ | D20: What is left from one more admission after paying the costs that only happen because we took it: clinician visit pay, mileage, supplies. It is not the revenue, and it does not include rent or management, which we pay anyway. | E20: Growth is only worth what it leaves behind after the cost of delivering it. Using revenue here instead would overstate the lever several times over. | F20: The 8.13 workbook | G20: From the workbook
A21: Revenue protected by preventing one short-visit period | B21: 1400 | C21: $ | D21: If a 30-day Medicare period ends with too few visits, Medicare stops paying the full period amount and pays a much smaller per-visit amount instead. This is what that costs us when it happens. | E21: It is a cliff, not a slope. One visit either side of the line changes the payment for the whole period, which is why timing matters more than volume. | F21: The 8.13 workbook | G21: From the workbook
A22: Margin per visit on non-Medicare payers | B22: 65 | C22: $ | D22: What one more visit leaves behind on an insurer who pays per visit, after paying the clinician for it. | E22: This is what a visit we failed to staff was worth. It only applies to the non-Medicare half of the book. | F22: Calculated: roughly $150 collected, less visit pay and other direct costs | G22: Our estimate
A23: Yearly cost of one scheduler | B23: 60000 | C23: $ | D23: Salary plus payroll taxes and benefits for one scheduling role. | E23: Multiplied by the number of roles no longer needed. Using salary alone would understate it by about a third. | F23: US Bureau of Labor Statistics median for this role, plus benefits | G23: Good
A24: Cost to replace one clinician who leaves | B24: 40000 | C24: $ | D24: Recruiting, onboarding, orientation, and the productivity lost while a new hire gets up to speed. | E24: Turns a reduction in people leaving into a dollar figure. | F24: The 8.13 workbook | G24: From the workbook
A25: Clinicians leaving per branch each year | B25: 5 | C25: count | D25: How many clinicians resign or are replaced at a typical branch in a year. | E25: Worth checking. Five per branch across 3,000 clinicians is about 13 percent a year, and published home health nursing turnover runs 25 to 28 percent. If we are closer to the published rate, this lever is worth roughly twice what the model shows. | F25: The 8.13 workbook | G25: Worth checking
A26: Premium labor spend per branch each year | B26: 120000 | C26: $ | D26: Money spent above our normal rate to get a visit covered: agency and contract clinicians, per diem staff at premium rates, overtime, and bonuses for picking up extra work. Contract staff are the most expensive form of it. | E26: It is bought in a hurry today because nobody can see who has room in their week. Seeing it in advance turns an emergency purchase into a planned assignment by someone already on the payroll. | F26: The 8.13 workbook | G26: From the workbook
A27: Yearly mileage spend across the company | B27: 16000000 | C27: $ | D27: What we reimburse clinicians for driving between patients. | E27: The travel lever is a percentage of this. The figure below is a placeholder we made up to show the shape of the calculation, and it must be replaced with the real number before anyone relies on it. | F27: Placeholder: 3,000 clinicians, 8,000 miles each, at $0.67 | G27: Made up, replace
A29: HOW MUCH BETTER WE THINK WE CAN GET
A30: Line item | B30: Low | C30: Middle | D30: High | E30: What this is, in plain terms | F30: Why it is here, and what it changes | G30: Where the range came from
A31: More admissions | B31: 0.02 | C31: 0.04 | D31: 0.07 | E31: The percentage more patients we start on service because a clinician's open slot gets filled instead of going to waste. | F31: A clinician's open start-of-care slot tomorrow either gets used or it disappears. It does not carry over to the next day. The faster we can answer yes or no, the more chances we have to fill it before it is gone. | G31: The only published figures available: 2 percent in hospitals, 4 to 15 percent in comparable field work
A32: Fewer visits going unstaffed | B32: 0.01 | C32: 0.02 | D32: 0.035 | E32: The percentage-point improvement in how many approved, needed visits actually get covered. The industry staffs about 88 to 90 out of every 100. | F32: When a patient cancels or a clinician calls out, the visit is often simply lost because nobody can quickly find who else could take it. On insurers who pay per visit, every one of those is money we had already earned the right to collect. | G32: Published industry staffing rates of 88 to 90 percent
A33: Fewer short-visit Medicare periods | B33: 0.005 | C33: 0.01 | D33: 0.02 | E33: The reduction in how often a 30-day Medicare period ends below the visit count that triggers the lower payment. | F33: Most of these miss by a single visit, and often because a visit was missed or moved rather than because fewer visits were needed. Seeing it coming while there are still days left is what makes it fixable. | G33: The 8.13 workbook's own low, middle and high figures
A34: Scheduler roles no longer needed | B34: 27 | C34: 60 | D34: 90 | E34: How many of the 300 scheduling roles the work no longer requires. | F34: Deliberately below the 300-to-100 figure discussed on site. The best published example of this software elsewhere freed 10 roles across 18 to 30 branches, which scales to 27 to 44 for us. The high figure comes from counting the specific tasks that would go away. | G34: A published customer example, plus a task-by-task count
A35: Premium labor turned into planned coverage | B35: 0.15 | C35: 0.3 | D35: 0.5 | E35: The share of agency, overtime and premium spend that could have been covered by someone already on the payroll, if we had seen it in time. | F35: Not all of it is avoidable. Real gaps still need paid cover. Note that with most clinicians paid per visit, the saving is the difference between our rate and the agency rate, not the whole agency bill. | G35: The 8.13 workbook's own low, middle and high figures
A36: Fewer clinicians leaving | B36: 0.05 | C36: 0.1 | D36: 0.2 | E36: The reduction in how many clinicians leave each year. | F36: A study of 3,716 home health nurses found that those with the most unpredictable week-to-week visit counts were far more likely to quit, and that steadying it cut the chance of leaving by 9 percentage points. The effect only showed up in full-time staff, which the authors put down to income mattering most to people who depend on the job. With most of our clinicians paid per visit, an unpredictable schedule is an unpredictable paycheck. | G36: The 8.13 workbook's figures, supported by the study above
A37: Less driving | B37: 0.05 | C37: 0.08 | D37: 0.12 | E37: The reduction in miles driven, by grouping each clinician's day sensibly and drawing territories around real drive times. | F37: Vendors claim 20 to 40 percent. The best-funded delivery routing program in the world reached 8 to 10 percent after thirteen years, so we have used the realistic range instead. | G37: Measured results from comparable field work
A39: WHAT THE PROGRAM COSTS
A40: Line item | B40: Low | C40: Middle | D40: High | E40: What this is, in plain terms | F40: Why it is here, and what it changes
A41: Putting it in and connecting it (one time) | B41: 1000000 | C41: 3400000 | D41: 8000000 | E41: Configuring the software and building the connections to our existing patient record system. | F41: Our patient record system has no ready-made way for outside software to connect to it, so this is built by hand. It is also the item most likely to run long, and delay costs us more than the fee does.
A42: Getting our data ready (one time) | B42: 500000 | C42: 1300000 | D42: 4000000 | E42: Cleaning up and organizing the information the software needs before it can produce anything useful. | F42: Scheduling software is only as good as the underlying information about who is qualified for what, who is available when, and what each insurer has approved. The most common cause of failure elsewhere is starting before this is right.
A43: Slower work while people learn it (one time) | B43: 400000 | C43: 1000000 | D43: 3000000 | E43: The temporary dip in output while everyone adjusts. | F43: Real and well documented, though the published evidence disagrees on size. One study found a lasting drop; another found a gain after six months. We have carried a range rather than pick a side.
A44: Software subscription (every year) | B44: 400000 | C44: 720000 | D44: 1500000 | E44: The annual fee to the software company. | F44: Worth knowing that this is about a tenth of the total. The fee is not where the money goes.
...

Sheet Value
A1: Where the money comes from
A2: Seven ways this program produces money, each shown at a low, middle and high assumption. Change the assumptions on the Inputs page and these move.
A4: What produces the money | B4: Low | C4: Middle | D4: High | E4: What is actually happening | F4: Why we believe it happens (cause and effect) | G4: How the number is worked out
A5: More patients started on service | B5: =Inputs!$B$13*Inputs!$B$31*Inputs!$B$20 -> 1152000 | C5: =Inputs!$B$13*Inputs!$C$31*Inputs!$B$20 -> 2304000 | D5: =Inputs!$B$13*Inputs!$D$31*Inputs!$B$20 -> 4032000 | E5: We take on more patients without hiring, because we can see who has room and answer the hospital faster. | F5: A clinician's open slot for tomorrow is like an empty seat on tomorrow's flight. If it is not filled, it is gone, and it does not come back the next day. Today the answer to whether we can take a patient is slow, so slots expire while we are still working it out. Answering faster means fewer expire. | G5: Admissions per year, times the percentage increase, times the margin one admission leaves behind
A6: Fewer approved visits going unstaffed | B6: =Inputs!$B$16*Inputs!$B$32*Inputs!$B$22 -> 1235000 | C6: =Inputs!$B$16*Inputs!$C$32*Inputs!$B$22 -> 2470000 | D6: =Inputs!$B$16*Inputs!$D$32*Inputs!$B$22 -> 4322500 | E6: When a visit falls through, someone else picks it up quickly instead of it being lost. | F6: This is a different group of people from the one above. Aides and assistants carry most of the weekly visits, and their work never produces an admission, so the two do not overlap. On insurers who pay per visit, a visit we could not staff is money we had already earned the right to collect and simply did not. | G6: Non-Medicare visits, times the improvement in how many get staffed, times the margin per visit
A7: Fewer Medicare periods falling short on visits | B7: =Inputs!$B$14*Inputs!$B$33*Inputs!$B$21 -> 560000 | C7: =Inputs!$B$14*Inputs!$C$33*Inputs!$B$21 -> 1120000 | D7: =Inputs!$B$14*Inputs!$D$33*Inputs!$B$21 -> 2240000 | E7: We spot a 30-day period heading for too few visits while there is still time to put a clinically needed visit back. | F7: Medicare pays a fixed amount for a 30-day period, but only if a minimum number of visits happen. Miss it and the whole period reprices downward. Most misses are by one visit, and usually because a visit was missed or moved, not because fewer were needed. Today we find out afterwards. Seeing it coming is the whole difference. Note we would never add a visit a patient does not need to reach the number. | G7: Medicare periods, times the reduction in short periods, times what one short period costs us
A8: Fewer scheduling roles needed | B8: =Inputs!$B$34*Inputs!$B$23 -> 1620000 | C8: =Inputs!$C$34*Inputs!$B$23 -> 3600000 | D8: =Inputs!$D$34*Inputs!$B$23 -> 5400000 | E8: Assigning visits takes far fewer people once the repetitive parts happen by themselves. | F8: Schedulers spend their day working a task list rather than making scheduling decisions, and the same patient generates a task for every discipline, twice over. Removing that work removes the need for the roles. Some of it should not exist at all, which means the software does not deserve credit for all of it. | G8: Roles no longer needed, times the yearly cost of a role including benefits
A9: Less premium labor | B9: =Inputs!$B$6*Inputs!$B$26*Inputs!$B$35 -> 1440000 | C9: =Inputs!$B$6*Inputs!$B$26*Inputs!$C$35 -> 2880000 | D9: =Inputs!$B$6*Inputs!$B$26*Inputs!$D$35 -> 4800000 | E9: Fewer visits covered by agency staff, overtime, or bonus pay because we could not find anyone else in time. | F9: When someone calls out at seven in the morning, nobody can see who has room, so the branch reaches for the most expensive option or loses the visit. Seeing available capacity turns an emergency purchase into a planned assignment. | G9: Branches, times premium spend per branch, times the share we could have covered another way
A10: Fewer clinicians leaving | B10: =Inputs!$B$6*Inputs!$B$25*Inputs!$B$36*Inputs!$B$24 -> 800000 | C10: =Inputs!$B$6*Inputs!$B$25*Inputs!$C$36*Inputs!$B$24 -> 1600000 | D10: =Inputs!$B$6*Inputs!$B$25*Inputs!$D$36*Inputs!$B$24 -> 3200000 | E10: A steadier, more predictable week means fewer clinicians resign, and we spend less replacing them. | F10: Most of our clinicians are paid per visit, so an unpredictable schedule is an unpredictable paycheck. A study of 3,716 home health nurses found the ones with the most erratic visit counts were markedly more likely to quit, and that steadying it cut the chance of leaving by 9 percentage points. It only held for full-time staff, which fits: it is people who depend on the income who leave over it. | G10: Branches, times clinicians leaving per branch, times the reduction, times replacement cost
A11: Less driving | B11: =Inputs!$B$27*Inputs!$B$37 -> 800000 | C11: =Inputs!$B$27*Inputs!$C$37 -> 1280000 | D11: =Inputs!$B$27*Inputs!$D$37 -> 1920000 | E11: Clinicians drive fewer miles because their day is grouped sensibly and territories follow real drive times. | F11: Territories today are drawn on maps by hand and rarely redrawn, and a day's visits are grouped by distance rather than by how long the drive actually takes. Note that with most clinicians paid per visit, the time saved belongs to them, not to us. What we save is the mileage we reimburse. The time they get back turns into capacity, which is counted in the first row, not here. | G11: Yearly mileage spend, times the reduction
A12: TOTAL EACH YEAR, once fully rolled out | B12: =SUM(B5:B11) -> 7607000 | C12: =SUM(C5:C11) -> 15254000 | D12: =SUM(D5:D11) -> 25914500 | E12: This is the yearly figure after every branch is live. What we collect in year one and year two is less, and the front page shows that.
A14: THINGS WE BELIEVE ARE REAL BUT HAVE NOT PUT A NUMBER ON
A15: Easier to recruit clinicians | B15: not yet | C15: not yet | D15: not yet | E15: Two reasons. Clinicians currently spend around half an hour every evening, unpaid, calling tomorrow's patients to confirm. That goes away. And a recruit who is quoted an expected income is far more likely to actually earn it when their week is protected and a canceled visit gets replaced. | F15: Left without a number because we do not yet track how long a vacancy takes to fill, how often offers are accepted, or what a hire costs us. Those four measures are on the Baseline page.
A16: The same approach applied to hospice | B16: not yet | C16: not yet | D16: not yet | E16: The 8.13 workbook notes that hospice needs a few added rules rather than a different product. | F16: Would roughly double what this is worth, at little extra cost. Left out until home health proves it.
A17: Visits we deliver and cannot bill | B17: not yet | C17: not yet | D17: not yet | E17: Insurers allow only a short window, often zero to five days, to backdate an approval. Care delivered outside it is written off. | F17: Nobody counts this today. It could be immaterial or it could be the largest item on this page. It is the first thing worth measuring.
A19: Two rules that stop us counting the same money twice
A20: The first two rows are different people. Nurses and therapists who admit patients are not the same group as the aides and assistants who carry the routine weekly visits, so both can improve at once without overlapping.
A21: The second row only counts insurers who pay per visit. On traditional Medicare, once the minimum visit count is met, an extra visit brings in nothing, so filling more of them there would be cost without income.

Sheet Cost
A1: What it costs us, over three years
A2: Follows the cost assumptions chosen on the Inputs page.
A4: Cost | B4: Year 1 | C4: Year 2 | D4: Year 3 | E4: Three years | F4: What this covers | G4: Why it is here
A5: =Inputs!A41 -> Putting it in and connecting it (one time) | B5: =INDEX(Inputs!$B$41:$D$41,Inputs!$B$58) -> 3400000 | C5: 0 | D5: 0 | E5: =SUM(B5:D5) -> 3400000 | F5: Configuring the software and building connections to our patient record system. | G5: Our record system has no ready-made connection method, so this is hand-built. Delay here costs more than the fee itself.
A6: =Inputs!A42 -> Getting our data ready (one time) | B6: =INDEX(Inputs!$B$42:$D$42,Inputs!$B$58) -> 1300000 | C6: 0 | D6: 0 | E6: =SUM(B6:D6) -> 1300000 | F6: Cleaning and organizing the information the software depends on. | G6: Scheduling software cannot work from information that is wrong about who is qualified, who is free, and what has been approved.
A7: =Inputs!A43 -> Slower work while people learn it (one time) | B7: =INDEX(Inputs!$B$43:$D$43,Inputs!$B$58) -> 1000000 | C7: 0 | D7: 0 | E7: =SUM(B7:D7) -> 1000000 | F7: The temporary dip in output while people learn the new way. | G7: Well documented elsewhere, though studies disagree on how big and how long, so we carry a wide range.
A8: =Inputs!A44 -> Software subscription (every year) | B8: =INDEX(Inputs!$B$44:$D$44,Inputs!$B$58) -> 720000 | C8: =INDEX(Inputs!$B$44:$D$44,Inputs!$B$58) -> 720000 | D8: =INDEX(Inputs!$B$44:$D$44,Inputs!$B$58) -> 720000 | E8: =SUM(B8:D8) -> 2160000 | F8: The yearly fee to the software company. | G8: About a tenth of the total. Worth saying out loud, because the fee is what people negotiate and it is not where the money goes.
A9: =Inputs!A45 -> Our own people's time (every year) | B9: =INDEX(Inputs!$B$45:$D$45,Inputs!$B$58) -> 3300000 | C9: =INDEX(Inputs!$B$45:$D$45,Inputs!$B$58) -> 3300000 | D9: =INDEX(Inputs!$B$45:$D$45,Inputs!$B$58) -> 3300000 | E9: =SUM(B9:D9) -> 9900000 | F9: Our own people working on this instead of their normal jobs. | G9: The biggest cost, roughly four times the software fee, and the one most often missing from business cases.
A10: =Inputs!A46 -> Helping people through the change (every year) | B10: =INDEX(Inputs!$B$46:$D$46,Inputs!$B$58) -> 830000 | C10: =INDEX(Inputs!$B$46:$D$46,Inputs!$B$58) -> 830000 | D10: =INDEX(Inputs!$B$46:$D$46,Inputs!$B$58) -> 830000 | E10: =SUM(B10:D10) -> 2490000 | F10: Training, coaching and support so people actually use it. | G10: The previous attempt failed here for this reason. Done well, programs meet their goals 88 percent of the time; done poorly, 13 percent.
A11: =Inputs!A47 -> Keeping it running (every year) | B11: =INDEX(Inputs!$B$47:$D$47,Inputs!$B$58) -> 350000 | C11: =INDEX(Inputs!$B$47:$D$47,Inputs!$B$58) -> 350000 | D11: =INDEX(Inputs!$B$47:$D$47,Inputs!$B$58) -> 350000 | E11: =SUM(B11:D11) -> 1050000 | F11: Support, updates, and keeping insurer and Medicare rules current. | G11: Insurer rules change quietly when contracts renew. A stale rule gives confident wrong answers.
A12: Severance for scheduling roles that end | B12: 0 | C12: =INDEX(Inputs!$B$34:$D$34,Inputs!$B$56)*Inputs!$B$23*0.25 -> 900000 | D12: 0 | E12: =SUM(B12:D12) -> 900000 | F12: Three months of pay for each role that ends, assumed to fall in year two. | G12: Left out of the earlier version. If we are counting the saving from roles ending, we have to count what ending them costs.
A13: TOTAL COST | B13: =SUM(B5:B12) -> 10900000 | C13: =SUM(C5:C12) -> 6100000 | D13: =SUM(D5:D12) -> 5200000 | E13: =SUM(E5:E12) -> 22200000

Sheet What we must measure
A1: What we have to measure before any of these numbers can be trusted
A2: Every figure in this model is either measured, published, or assumed. This is the list that turns the assumed ones into measured ones. Anything marked no in the fifth column does not exist today.
A4: What to measure | B4: What it tells us | C4: Which value it supports | D4: Where it lives | E4: Do we have it | F4: How to get it | G4: Effort
A5: Admissions per year | B5: How many new patients we start on service, company wide | C5: More patients started | D5: Patient record system | E5: Yes | F5: Count new starts by branch for twelve months | G5: Low
A6: Time from referral to first visit | B6: How long a patient waits between us accepting them and being seen | C6: More patients started | D6: Intake and patient record systems | E6: Partly | F6: Timestamps at each handoff: accepted, insurance cleared, approved, called, scheduled, seen | G6: Medium
A7: Referrals we turned down for lack of capacity | B7: How much business we are declining because we cannot staff it | C7: More patients started | D7: Referral log | E7: No | F7: Needs a reason code that does not exist today | G7: High
A8: Open start-of-care slots offered against filled | B8: How much admitting capacity goes to waste | C8: More patients started | D8: Patient record system | E8: No | F8: Needs a shared definition of an open slot first | G8: High
A9: Share of approved visits that get staffed | B9: How often an approved, needed visit never happens | C9: Fewer visits unstaffed | D9: Patient record system | E9: Partly | F9: Scheduled against completed against canceled, split by insurer type | G9: Medium
A10: Who does which visits | B10: The split between nurses and aides, therapists and assistants | C10: Fewer visits unstaffed | D10: Patient record system | E10: Yes | F10: Visit counts by discipline for twelve months | G10: Low
A11: Cancellations and refusals | B11: How often visits fall through, why, and who absorbs the cost | C11: Fewer visits unstaffed | D11: Patient record system | E11: Partly | F11: Reasons are captured for some outcomes but not for refusals | G11: Medium
A12: How long a canceled visit takes to refill | B12: Whether a freed slot gets reused or lost | C12: Fewer visits unstaffed | D12: Patient record system | E12: No | F12: Derived from cancellation and reassignment timestamps | G12: Medium
A13: How often Medicare periods fall short on visits | B13: Our real rate, and how many missed by only one visit | C13: Fewer short periods | D13: Billing | E13: Partly | F13: Claims compared against the Medicare threshold table | G13: Medium
A14: Why those periods fell short | B14: Whether fewer visits were clinically right, or a visit was simply lost | C14: Fewer short periods | D14: Billing and patient record | E14: No | F14: Match short periods to missed and moved visits | G14: High
A15: What schedulers actually do all day | B15: Task volumes and how long each really takes | C15: Fewer scheduling roles | D15: Patient record system | E15: Yes | F15: Ninety days of task records with start and finish times. This is a report, not a study | G15: Low
... A28: Why people say they left | B28: Departure reasons, coded the same way each time | C28: Fewer leaving, easier recruiting | D28: HR system | E28: Partly | F28: Separates schedule and income causes from everything else | G28: Medium
A30: The short version: five of these are marked low effort and already exist. Together they support five of the seven ways this program makes money, and all five are reports against systems we already own. That is a two-week request, not a project.
